Workbook

Sheet phi0
A1: 1. Calculate unfished spawning biomass per recruit (phi0) | E1: At-age - Biological Data (estimated)
C2: Parameter | E2: 1 | F2: 2 | G2: 3 | H2: 4 | I2: 5 | J2: 6 | K2: 7 | L2: 8 | M2: 9 | N2: 10 | O2: 11+ | P2: units | Q2: Comments
C3: Weight-at-age | D3: w_age | E3: 0.014514176 | F3: 0.042231692 | G3: 0.10022034 | H3: 0.15438523 | I3: 0.19563793 | J3: 0.22963509 | K3: 0.25884311 | L3: 0.28409739 | M3: 0.3044291 | N3: 0.31988238 | O3: 0.33599304 | P3: kg | Q3: User defined: estimated from biological sampling
C4: Proportion mature | D4: m_age | E4: 0.0054683992 | F4: 0.036348653 | G4: 0.39111466 | H4: 0.88567802 | I4: 0.98410829 | J4: 0.99653237 | K4: 0.99897673 | L4: 0.99966407 | M4: 0.99988525 | N4: 0.99996004 | O4: 0.99998593 | P4: - | Q4: User defined: estimated from biological sampling
C5: M | D5: M | E5: 0.35 | F5: 0.35 | G5: 0.35 | H5: 0.35 | I5: 0.35 | J5: 0.35 | K5: 0.35 | L5: 0.35 | M5: 0.35 | N5: 0.35 | O5: 0.35 | P5: - | Q5: User defined: model assumption
C6: Unfished survivorship | D6: l0_age | E6: 1 | F6: =E6*EXP(-E5) -> 0.70468809 | G6: =F6*EXP(-F5) -> 0.4965853 | H6: =G6*EXP(-G5) -> 0.34993775 | I6: =H6*EXP(-H5) -> 0.24659696 | J6: =I6*EXP(-I5) -> 0.17377394 | K6: =J6*EXP(-J5) -> 0.12245643 | L6: =K6*EXP(-K5) -> 0.086293586 | M6: =L6*EXP(-L5) -> 0.060810063 | N6: =M6*EXP(-M5) -> 0.042852127 | O6: =N6*EXP(-N5)/(1-EXP(-O5)) -> 0.10225589 | P6: - | Q6: unfished so use F=0
C7: Unfished spawning biomass (or eggs) per recruit | D7: φ0 | E7: =SUMPRODUCT(E6:O6,E3:O3,E4:O4) -> 0.27846452 | P7: kg/recruit
C16: Equilibrium survivorship-at-age: | I16: va = vulnerability-at-age
C21: Equilibrium spawning biomass per recruit:
C25: Note:
C26: Equilibrium eggs per recruit: | G26: fa = relative fecundity (eggs per units mass). A common assumption is fecundity is proportional to spawning biomass.

Sheet SPR and YPR
A1: 2. Calculate spawning biomass per recruit for various F
C2: Parameter | E2: 1 | F2: 2 | G2: 3 | H2: 4 | I2: 5 | J2: 6 | K2: 7 | L2: 8 | M2: 9 | N2: 10 | O2: 11+ | P2: units | Q2: Comments
C3: Weight-at-age | D3: w_age | E3: 0.014514176 | F3: 0.042231692 | G3: 0.10022034 | H3: 0.15438523 | I3: 0.19563793 | J3: 0.22963509 | K3: 0.25884311 | L3: 0.28409739 | M3: 0.3044291 | N3: 0.31988238 | O3: 0.33599304 | P3: kg | Q3: User defined: estimated from biological sampling
C4: Proportion mature | D4: m_age | E4: 0.0054683992 | F4: 0.036348653 | G4: 0.39111466 | H4: 0.88567802 | I4: 0.98410829 | J4: 0.99653237 | K4: 0.99897673 | L4: 0.99966407 | M4: 0.99988525 | N4: 0.99996004 | O4: 0.99998593 | P4: - | Q4: User defined: estimated from biological sampling
A5: Start with F = | B5: 0.1 | C5: M | D5: M_age | E5: 0.35 | F5: 0.35 | G5: 0.35 | H5: 0.35 | I5: 0.35 | J5: 0.35 | K5: 0.35 | L5: 0.35 | M5: 0.35 | N5: 0.35 | O5: 0.35 | P5: - | Q5: User defined: model assumption
C6: Unfished survivorship | D6: l0_age | E6: 1 | F6: =E6*EXP(-E5) -> 0.70468809 | G6: =F6*EXP(-F5) -> 0.4965853 | H6: =G6*EXP(-G5) -> 0.34993775 | I6: =H6*EXP(-H5) -> 0.24659696 | J6: =I6*EXP(-I5) -> 0.17377394 | K6: =J6*EXP(-J5) -> 0.12245643 | L6: =K6*EXP(-K5) -> 0.086293586 | M6: =L6*EXP(-L5) -> 0.060810063 | N6: =M6*EXP(-M5) -> 0.042852127 | O6: =N6*EXP(-N5)/(1-EXP(-O5)) -> 0.10225589 | P6: - | Q6: unfished so use F=0
C7: Unfished spawning biomass (or eggs) per recruit | D7: φ0 | E7: =SUMPRODUCT(E6:O6,E3:O3,E4:O4) -> 0.27846452 | P7: kg/recruit
C8: Vulnerability (selectivity) | D8: v_age | E8: 0.036261919 | F8: 0.44203881 | G8: 0.95338308 | H8: 0.97124384 | I8: 0.98163231 | J8: 0.97975931 | K8: 0.97361862 | L8: 0.96596968 | M8: 0.95949061 | N8: 0.95474833 | O8: 0.95125692 | P8: - | Q8: User defined: Model output
C9: Fishing mortality rate | D9: F | E9: =B5 -> 0.1 | P9: -
C10: Fished survivorship | D10: lF_age | E10: 1 | F10: =E10*EXP(-E5-$E$9*E8) -> 0.70213738 | G10: =F10*EXP(-F5-$E$9*F8) -> 0.47339267 | H10: =G10*EXP(-G5-$E$9*G8) -> 0.3032589 | I10: =H10*EXP(-H5-$E$9*H8) -> 0.19392326 | J10: =I10*EXP(-I5-$E$9*I8) -> 0.12387826 | K10: =J10*EXP(-J5-$E$9*J8) -> 0.079148304 | L10: =K10*EXP(-K5-$E$9*K8) -> 0.050600502 | M10: =L10*EXP(-L5-$E$9*L8) -> 0.032374288 | N10: =M10*EXP(-M5-$E$9*M8) -> 0.020726549 | O10: =N10*EXP(-N5-$E$9*N8)/(1-EXP(-O5-$E$9*O8)) -> 0.036953484 | P10: -
C11: Fished spawning biomass (or eggs) per recruit | D11: φF | E11: =SUMPRODUCT(E10:O10,E3:O3,E4:O4) -> 0.19060029 | P11: kg/recruit
C12: Spawning potential ratio | D12: SPR | E12: =E11/E7 -> 0.68446886 | P12: -
C13: Yield per recruit-at-age | D13: YPR_age | E13: =E10*E3*$E$9*E8*(1-EXP(-$E$9*E8-E5))/($E$9*E8+E5) -> 4.4331737e-05 | F13: =F10*F3*$E$9*F8*(1-EXP(-$E$9*F8-F5))/($E$9*F8+F5) -> 0.0010832509 | G13: =G10*G3*$E$9*G8*(1-EXP(-$E$9*G8-G5))/($E$9*G8+G5) -> 0.0036502598 | H13: =H10*H3*$E$9*H8*(1-EXP(-$E$9*H8-H5))/($E$9*H8+H5) -> 0.0036666328 | I13: =I10*I3*$E$9*I8*(1-EXP(-$E$9*I8-I5))/($E$9*I8+I5) -> 0.0030015311 | J13: =J10*J3*$E$9*J8*(1-EXP(-$E$9*J8-J5))/($E$9*J8+J5) -> 0.0022464741 | K13: =K10*K3*$E$9*K8*(1-EXP(-$E$9*K8-K5))/($E$9*K8+K5) -> 0.0016081968 | L13: =L10*L3*$E$9*L8*(1-EXP(-$E$9*L8-L5))/($E$9*L8+L5) -> 0.001119983 | ... O13: =O10*O3*$E$9*O8*(1-EXP(-$E$9*O8-O5))/($E$9*O8+O5) -> 0.00095324646 | P13: kg
C14: Yield per recruit | D14: YPR | E14: =SUM(E13:O13) -> 0.018647642 | P14: kg
C18: Spawning Potential Ratio: | F18: Ratio of (spawning biomass per recruit in the fished state) to (spawning biomass per recruit in the unfished state)
C21: Yield Per Recruit :

Sheet Curves and SPRx
A1: 2. Calculate spawning biomass per recruit for various F
C2: Parameter | E2: 1 | F2: 2 | G2: 3 | H2: 4 | I2: 5 | J2: 6 | K2: 7 | L2: 8 | M2: 9 | N2: 10 | O2: 11+ | P2: units | Q2: Comments
C3: Weight-at-age | D3: w_age | E3: 0.014514176 | F3: 0.042231692 | G3: 0.10022034 | H3: 0.15438523 | I3: 0.19563793 | J3: 0.22963509 | K3: 0.25884311 | L3: 0.28409739 | M3: 0.3044291 | N3: 0.31988238 | O3: 0.33599304 | P3: kg | Q3: User defined: estimated from biological sampling
C4: Proportion mature | D4: m_age | E4: 0.0054683992 | F4: 0.036348653 | G4: 0.39111466 | H4: 0.88567802 | I4: 0.98410829 | J4: 0.99653237 | K4: 0.99897673 | L4: 0.99966407 | M4: 0.99988525 | N4: 0.99996004 | O4: 0.99998593 | P4: - | Q4: User defined: estimated from biological sampling
A5: Start with F = | B5: 0.1 | C5: M | D5: M_age | E5: 0.35 | F5: 0.35 | G5: 0.35 | H5: 0.35 | I5: 0.35 | J5: 0.35 | K5: 0.35 | L5: 0.35 | M5: 0.35 | N5: 0.35 | O5: 0.35 | P5: - | Q5: User defined: model assumption
C6: Unfished survivorship | D6: l0_age | E6: 1 | F6: =E6*EXP(-E5) -> 0.70468809 | G6: =F6*EXP(-F5) -> 0.4965853 | H6: =G6*EXP(-G5) -> 0.34993775 | I6: =H6*EXP(-H5) -> 0.24659696 | J6: =I6*EXP(-I5) -> 0.17377394 | K6: =J6*EXP(-J5) -> 0.12245643 | L6: =K6*EXP(-K5) -> 0.086293586 | M6: =L6*EXP(-L5) -> 0.060810063 | N6: =M6*EXP(-M5) -> 0.042852127 | O6: =N6*EXP(-N5)/(1-EXP(-O5)) -> 0.10225589 | P6: - | Q6: unfished so use F=0
C7: Unfished spawning biomass (or eggs) per recruit | D7: φ0 | E7: =SUMPRODUCT(E6:O6,E3:O3,E4:O4) -> 0.27846452 | P7: kg/recruit
A8: 3. Add what-if analysis to calculate SPR and YPR for various F | C8: Vulnerability (selectivity) | D8: v_age | E8: 0.036261919 | F8: 0.44203881 | G8: 0.95338308 | H8: 0.97124384 | I8: 0.98163231 | J8: 0.97975931 | K8: 0.97361862 | L8: 0.96596968 | M8: 0.95949061 | N8: 0.95474833 | O8: 0.95125692 | P8: - | Q8: User defined: Model output
C9: Fishing mortality rate | D9: F | E9: =B5 -> 0.1 | P9: -
C10: Fished survivorship | D10: lF_age | E10: 1 | F10: =E10*EXP(-E5-$E$9*E8) -> 0.70213738 | G10: =F10*EXP(-F5-$E$9*F8) -> 0.47339267 | H10: =G10*EXP(-G5-$E$9*G8) -> 0.3032589 | I10: =H10*EXP(-H5-$E$9*H8) -> 0.19392326 | J10: =I10*EXP(-I5-$E$9*I8) -> 0.12387826 | K10: =J10*EXP(-J5-$E$9*J8) -> 0.079148304 | L10: =K10*EXP(-K5-$E$9*K8) -> 0.050600502 | M10: =L10*EXP(-L5-$E$9*L8) -> 0.032374288 | N10: =M10*EXP(-M5-$E$9*M8) -> 0.020726549 | O10: =N10*EXP(-N5-$E$9*N8)/(1-EXP(-O5-$E$9*O8)) -> 0.036953484 | P10: -
C11: Fished spawning biomass (or eggs) per recruit | D11: φF | E11: =SUMPRODUCT(E10:O10,E3:O3,E4:O4) -> 0.19060029 | P11: kg/recruit
C12: Spawning potential ratio | D12: SPR | E12: =E11/E7 -> 0.68446886 | P12: -
C13: Yield per recruit-at-age | D13: YPR_age | E13: =E10*E3*$E$9*E8*(1-EXP(-$E$9*E8-E5))/($E$9*E8+E5) -> 4.4331737e-05 | F13: =F10*F3*$E$9*F8*(1-EXP(-$E$9*F8-F5))/($E$9*F8+F5) -> 0.0010832509 | G13: =G10*G3*$E$9*G8*(1-EXP(-$E$9*G8-G5))/($E$9*G8+G5) -> 0.0036502598 | H13: =H10*H3*$E$9*H8*(1-EXP(-$E$9*H8-H5))/($E$9*H8+H5) -> 0.0036666328 | I13: =I10*I3*$E$9*I8*(1-EXP(-$E$9*I8-I5))/($E$9*I8+I5) -> 0.0030015311 | J13: =J10*J3*$E$9*J8*(1-EXP(-$E$9*J8-J5))/($E$9*J8+J5) -> 0.0022464741 | K13: =K10*K3*$E$9*K8*(1-EXP(-$E$9*K8-K5))/($E$9*K8+K5) -> 0.0016081968 | L13: =L10*L3*$E$9*L8*(1-EXP(-$E$9*L8-L5))/($E$9*L8+L5) -> 0.001119983 | ... O13: =O10*O3*$E$9*O8*(1-EXP(-$E$9*O8-O5))/($E$9*O8+O5) -> 0.00095324646 | P13: kg
C14: Yield per recruit | D14: YPR | E14: =SUM(E13:O13) -> 0.018647642 | P14: kg
Q15: User defined: needed to estiamte equilibrium SSB at F at X% SPR
C18: Spawning Potential Ratio: | F18: Ratio of (spawning biomass per recruit in the fished state) to (spawning biomass per recruit in the unfished state)
A19: 4. Estimate F at X% SPR
A20: X = | B20: 40 | C20: %
A21: F= | B21: =VLOOKUP(L27,L30:M280,2,FALSE) -> 0.28 | C21: Yield Per Recruit :
L25: Used to estimate F at X% SPR
L26: min SPR-X
A27: What if analysis to calculate SPR and YPR for different F | L27: =MIN(L30:L280) -> 0.0017042408
A28: F | B28: SPR | C28: YPR | L28: SPR-X | M28: F
B29: =E12 -> 0.68446886 | C29: =E14 -> 0.018647642
A30: 0.0001 | B30: 0.99957921 | C30: 2.6831244e-05 | L30: =ABS(B30-$B$20/100) -> 0.59957921 | M30: =A30 -> 0.0001
A31: 0.01 | B31: 0.95923693 | C31: 0.0025782733 | L31: =ABS(B31-$B$20/100) -> 0.55923693 | M31: =A31 -> 0.01
A32: 0.02 | B32: 0.92098392 | C32: 0.0049577543 | L32: =ABS(B32-$B$20/100) -> 0.52098392 | M32: =A32 -> 0.02
A33: 0.03 | B33: 0.88503528 | C33: 0.0071564694 | L33: =ABS(B33-$B$20/100) -> 0.48503528 | M33: =A33 -> 0.03
A34: 0.04 | B34: 0.85120627 | C34: 0.0091905063 | L34: =ABS(B34-$B$20/100) -> 0.45120627 | M34: =A34 -> 0.04
A35: 0.05 | B35: 0.81933061 | C35: 0.011074257 | L35: =ABS(B35-$B$20/100) -> 0.41933061 | M35: =A35 -> 0.05
A36: 0.06 | B36: 0.78925821 | C36: 0.012820626 | L36: =ABS(B36-$B$20/100) -> 0.38925821 | M36: =A36 -> 0.06
A37: 0.07 | B37: 0.76085334 | C37: 0.014441208 | L37: =ABS(B37-$B$20/100) -> 0.36085334 | M37: =A37 -> 0.07
A38: 0.08 | B38: 0.73399298 | C38: 0.015946443 | L38: =ABS(B38-$B$20/100) -> 0.33399298 | M38: =A38 -> 0.08
A39: 0.09 | B39: 0.70856539 | C39: 0.01734575 | L39: =ABS(B39-$B$20/100) -> 0.30856539 | M39: =A39 -> 0.09
A40: 0.1 | B40: 0.68446886 | C40: 0.018647642 | L40: =ABS(B40-$B$20/100) -> 0.28446886 | M40: =A40 -> 0.1
A41: 0.11 | B41: 0.66161069 | C41: 0.019859829 | L41: =ABS(B41-$B$20/100) -> 0.26161069 | M41: =A41 -> 0.11
... A280: 2.5 | B280: 0.030222125 | C280: 0.030503012 | L280: =ABS(B280-$B$20/100) -> 0.36977787 | M280: =A280 -> 2.5

Sheet SSB at SPRx
A1: 2. Calculate spawning biomass per recruit for various F
C2: Parameter | E2: 1 | F2: 2 | G2: 3 | H2: 4 | I2: 5 | J2: 6 | K2: 7 | L2: 8 | M2: 9 | N2: 10 | O2: 11+ | P2: units | Q2: Comments
C3: Weight-at-age | D3: w_age | E3: 0.014514176 | F3: 0.042231692 | G3: 0.10022034 | H3: 0.15438523 | I3: 0.19563793 | J3: 0.22963509 | K3: 0.25884311 | L3: 0.28409739 | M3: 0.3044291 | N3: 0.31988238 | O3: 0.33599304 | P3: kg | Q3: User defined: estimated from biological sampling
C4: Proportion mature | D4: m_age | E4: 0.0054683992 | F4: 0.036348653 | G4: 0.39111466 | H4: 0.88567802 | I4: 0.98410829 | J4: 0.99653237 | K4: 0.99897673 | L4: 0.99966407 | M4: 0.99988525 | N4: 0.99996004 | O4: 0.99998593 | P4: - | Q4: User defined: estimated from biological sampling
A5: Start with F = | B5: 0.1 | C5: M | D5: M_age | E5: 0.35 | F5: 0.35 | G5: 0.35 | H5: 0.35 | I5: 0.35 | J5: 0.35 | K5: 0.35 | L5: 0.35 | M5: 0.35 | N5: 0.35 | O5: 0.35 | P5: - | Q5: User defined: model assumption
C6: Unfished survivorship | D6: l0_age | E6: 1 | F6: =E6*EXP(-E5) -> 0.70468809 | G6: =F6*EXP(-F5) -> 0.4965853 | H6: =G6*EXP(-G5) -> 0.34993775 | I6: =H6*EXP(-H5) -> 0.24659696 | J6: =I6*EXP(-I5) -> 0.17377394 | K6: =J6*EXP(-J5) -> 0.12245643 | L6: =K6*EXP(-K5) -> 0.086293586 | M6: =L6*EXP(-L5) -> 0.060810063 | N6: =M6*EXP(-M5) -> 0.042852127 | O6: =N6*EXP(-N5)/(1-EXP(-O5)) -> 0.10225589 | P6: - | Q6: unfished so use F=0
C7: Unfished spawning biomass (or eggs) per recruit | D7: φ0 | E7: =SUMPRODUCT(E6:O6,E3:O3,E4:O4) -> 0.27846452 | P7: kg/recruit
A8: 3. Add what-if analysis to calculate SPR and YPR for various F | C8: Vulnerability (selectivity) | D8: v_age | E8: 0.036261919 | F8: 0.44203881 | G8: 0.95338308 | H8: 0.97124384 | I8: 0.98163231 | J8: 0.97975931 | K8: 0.97361862 | L8: 0.96596968 | M8: 0.95949061 | N8: 0.95474833 | O8: 0.95125692 | P8: - | Q8: User defined: Model output
C9: Fishing mortality rate | D9: F | E9: =B5 -> 0.1 | P9: -
C10: Fished survivorship | D10: lF_age | E10: 1 | F10: =E10*EXP(-E5-$E$9*E8) -> 0.70213738 | G10: =F10*EXP(-F5-$E$9*F8) -> 0.47339267 | H10: =G10*EXP(-G5-$E$9*G8) -> 0.3032589 | I10: =H10*EXP(-H5-$E$9*H8) -> 0.19392326 | J10: =I10*EXP(-I5-$E$9*I8) -> 0.12387826 | K10: =J10*EXP(-J5-$E$9*J8) -> 0.079148304 | L10: =K10*EXP(-K5-$E$9*K8) -> 0.050600502 | M10: =L10*EXP(-L5-$E$9*L8) -> 0.032374288 | N10: =M10*EXP(-M5-$E$9*M8) -> 0.020726549 | O10: =N10*EXP(-N5-$E$9*N8)/(1-EXP(-O5-$E$9*O8)) -> 0.036953484 | P10: -
C11: Fished spawning biomass (or eggs) per recruit | D11: φF | E11: =SUMPRODUCT(E10:O10,E3:O3,E4:O4) -> 0.19060029 | P11: kg/recruit
C12: Spawning potential ratio | D12: SPR | E12: =E11/E7 -> 0.68446886 | P12: -
C13: Yield per recruit-at-age | D13: YPR_age | E13: =E10*E3*$E$9*E8*(1-EXP(-$E$9*E8-E5))/($E$9*E8+E5) -> 4.4331737e-05 | F13: =F10*F3*$E$9*F8*(1-EXP(-$E$9*F8-F5))/($E$9*F8+F5) -> 0.0010832509 | G13: =G10*G3*$E$9*G8*(1-EXP(-$E$9*G8-G5))/($E$9*G8+G5) -> 0.0036502598 | H13: =H10*H3*$E$9*H8*(1-EXP(-$E$9*H8-H5))/($E$9*H8+H5) -> 0.0036666328 | I13: =I10*I3*$E$9*I8*(1-EXP(-$E$9*I8-I5))/($E$9*I8+I5) -> 0.0030015311 | J13: =J10*J3*$E$9*J8*(1-EXP(-$E$9*J8-J5))/($E$9*J8+J5) -> 0.0022464741 | K13: =K10*K3*$E$9*K8*(1-EXP(-$E$9*K8-K5))/($E$9*K8+K5) -> 0.0016081968 | L13: =L10*L3*$E$9*L8*(1-EXP(-$E$9*L8-L5))/($E$9*L8+L5) -> 0.001119983 | ... O13: =O10*O3*$E$9*O8*(1-EXP(-$E$9*O8-O5))/($E$9*O8+O5) -> 0.00095324646 | P13: kg
C14: Yield per recruit | D14: YPR | E14: =SUM(E13:O13) -> 0.018647642 | P14: kg
C15: Equilibrium unfished recruitment or median recruitment (no stock recruitment relationship) | D15: R | E15: =3.505041*1000 -> 3505.041 | P15: 10^6 recruits | Q15: User defined: Model output
A19: 4. Estimate F at X% SPR | F19: 0
A20: X = | B20: 40 | C20: %
A21: F= | B21: =VLOOKUP(L31,L34:M284,2,FALSE) -> 0.28
C23: Equilibrium fished SSB (no stock recruitment relationship) | D23: Eq_SSBF | E23: =VLOOKUP(B5,A34:E284,5,FALSE) -> 668.06185 | P23: kt | Q23: Biomass units come from product of weight-at-age and units of R
A26: 5. Estimate Equilibrium SSB at F at X% SPR (no stock recruitment relationship)
C27: =CONCATENATE("Equilibrium SSB at F at ",B20,"% SPR") -> Equilibrium SSB at F at 40% SPR | D27: =CONCATENATE("SSB F",B20,"%") -> SSB F40% | E27: =VLOOKUP(B21,A34:E284,5,FALSE) -> 392.07522 | P27: kt
L29: Used to estimate F at X% SPR
L30: min SPR-X
A31: What if analysis for different F | L31: =MIN(L34:L284) -> 0.0017042408
A32: F | B32: SPR | C32: YPR | D32: φF | E32: Eq_SSBF | L32: SPR-X | M32: F
B33: =E12 -> 0.68446886 | C33: =E14 -> 0.018647642 | D33: =E11 -> 0.19060029
A34: 0.0001 | B34: 0.99957921 | C34: 2.6831244e-05 | D34: 0.27834735 | E34: =D34*$E$15 -> 975.61886 | L34: =ABS(B34-$B$20/100) -> 0.59957921 | M34: =A34 -> 0.0001
A35: 0.01 | B35: 0.95923693 | C35: 0.0025782733 | D35: 0.26711345 | E35: =D35*$E$15 -> 936.2436 | L35: =ABS(B35-$B$20/100) -> 0.55923693 | M35: =A35 -> 0.01
A36: 0.02 | B36: 0.92098392 | C36: 0.0049577543 | D36: 0.25646135 | E36: =D36*$E$15 -> 898.90753 | L36: =ABS(B36-$B$20/100) -> 0.52098392 | M36: =A36 -> 0.02
A37: 0.03 | B37: 0.88503528 | C37: 0.0071564694 | D37: 0.24645092 | E37: =D37*$E$15 -> 863.8206 | L37: =ABS(B37-$B$20/100) -> 0.48503528 | M37: =A37 -> 0.03
A38: 0.04 | B38: 0.85120627 | C38: 0.0091905063 | D38: 0.23703075 | E38: =D38*$E$15 -> 830.80249 | L38: =ABS(B38-$B$20/100) -> 0.45120627 | M38: =A38 -> 0.04
A39: 0.05 | B39: 0.81933061 | C39: 0.011074257 | D39: 0.22815451 | E39: =D39*$E$15 -> 799.6909 | L39: =ABS(B39-$B$20/100) -> 0.41933061 | M39: =A39 -> 0.05
A40: 0.06 | B40: 0.78925821 | C40: 0.012820626 | D40: 0.21978041 | E40: =D40*$E$15 -> 770.33935 | L40: =ABS(B40-$B$20/100) -> 0.38925821 | M40: =A40 -> 0.06
A41: 0.07 | B41: 0.76085334 | C41: 0.014441208 | D41: 0.21187066 | E41: =D41*$E$15 -> 742.61536 | L41: =ABS(B41-$B$20/100) -> 0.36085334 | M41: =A41 -> 0.07
A42: 0.08 | B42: 0.73399298 | C42: 0.015946443 | D42: 0.204391 | E42: =D42*$E$15 -> 716.39885 | L42: =ABS(B42-$B$20/100) -> 0.33399298 | M42: =A42 -> 0.08
A43: 0.09 | B43: 0.70856539 | C43: 0.01734575 | D43: 0.19731032 | E43: =D43*$E$15 -> 691.58077 | L43: =ABS(B43-$B$20/100) -> 0.30856539 | M43: =A43 -> 0.09
A44: 0.1 | B44: 0.68446886 | C44: 0.018647642 | D44: 0.19060029 | E44: =D44*$E$15 -> 668.06185 | L44: =ABS(B44-$B$20/100) -> 0.28446886 | M44: =A44 -> 0.1
A45: 0.11 | B45: 0.66161069 | C45: 0.019859829 | D45: 0.1842351 | E45: =D45*$E$15 -> 645.7516 | L45: =ABS(B45-$B$20/100) -> 0.26161069 | M45: =A45 -> 0.11
... A284: 2.5 | B284: 0.030222125 | C284: 0.030503012 | D284: 0.0084157897 | E284: =D284*$E$15 -> 29.497688 | L284: =ABS(B284-$B$20/100) -> 0.36977787 | M284: =A284 -> 2.5

Sheet SRR and Yield
A1: 6. Add a B-H SRR from steepness (h) and equilibrium unfished recruitment (R0) | AD1: Recruitment (10^9) | AE1: SSB (kt)
C2: Parameter | E2: 1 | F2: 2 | G2: 3 | H2: 4 | I2: 5 | J2: 6 | K2: 7 | L2: 8 | M2: 9 | N2: 10 | O2: 11+ | P2: units | Q2: Comments | AD2: =$E$17*AE2/(1+$E$18*AE2) -> 4.3044949 | AE2: 0.1
C3: Weight-at-age | D3: w_age | E3: 0.014514176 | F3: 0.042231692 | G3: 0.10022034 | H3: 0.15438523 | I3: 0.19563793 | J3: 0.22963509 | K3: 0.25884311 | L3: 0.28409739 | M3: 0.3044291 | N3: 0.31988238 | O3: 0.33599304 | P3: kg | Q3: User defined: estimated from biological sampling | AD3: =$E$17*AE3/(1+$E$18*AE3) -> 387.2868 | AE3: 10
C4: Proportion mature | D4: m_age | E4: 0.0054683992 | F4: 0.036348653 | G4: 0.39111466 | H4: 0.88567802 | I4: 0.98410829 | J4: 0.99653237 | K4: 0.99897673 | L4: 0.99966407 | M4: 0.99988525 | N4: 0.99996004 | O4: 0.99998593 | P4: - | Q4: User defined: estimated from biological sampling | AD4: =$E$17*AE4/(1+$E$18*AE4) -> 703.33532 | AE4: 20
A5: Start with F = | B5: 0.1 | C5: M | D5: M_age | E5: 0.35 | F5: 0.35 | G5: 0.35 | H5: 0.35 | I5: 0.35 | J5: 0.35 | K5: 0.35 | L5: 0.35 | M5: 0.35 | N5: 0.35 | O5: 0.35 | P5: - | Q5: User defined: model assumption | AD5: =$E$17*AE5/(1+$E$18*AE5) -> 966.14563 | AE5: 30
C6: Unfished survivorship | D6: l0_age | E6: 1 | F6: =E6*EXP(-E5) -> 0.70468809 | G6: =F6*EXP(-F5) -> 0.4965853 | H6: =G6*EXP(-G5) -> 0.34993775 | I6: =H6*EXP(-H5) -> 0.24659696 | J6: =I6*EXP(-I5) -> 0.17377394 | K6: =J6*EXP(-J5) -> 0.12245643 | L6: =K6*EXP(-K5) -> 0.086293586 | M6: =L6*EXP(-L5) -> 0.060810063 | N6: =M6*EXP(-M5) -> 0.042852127 | O6: =N6*EXP(-N5)/(1-EXP(-O5)) -> 0.10225589 | P6: - | Q6: unfished so use F=0 | AD6: =$E$17*AE6/(1+$E$18*AE6) -> 1188.1247 | AE6: 40
C7: Unfished spawning biomass (or eggs) per recruit | D7: φ0 | E7: =SUMPRODUCT(E6:O6,E3:O3,E4:O4) -> 0.27846452 | P7: kg/recruit | AD7: =$E$17*AE7/(1+$E$18*AE7) -> 1378.1021 | AE7: 50
C8: Vulnerability (selectivity) | D8: v_age | E8: 0.036261919 | F8: 0.44203881 | G8: 0.95338308 | H8: 0.97124384 | I8: 0.98163231 | J8: 0.97975931 | K8: 0.97361862 | L8: 0.96596968 | M8: 0.95949061 | N8: 0.95474833 | O8: 0.95125692 | P8: - | Q8: User defined: Model output | AD8: =$E$17*AE8/(1+$E$18*AE8) -> 1542.533 | AE8: 60
A9: 7. Calculate equilbrium fished recruitment and equilibrium fished SSB | C9: Fishing mortality rate | D9: F | E9: =B5 -> 0.1 | P9: - | AD9: =$E$17*AE9/(1+$E$18*AE9) -> 1686.2455 | AE9: 70
C10: Fished survivorship | D10: lF_age | E10: 1 | F10: =E10*EXP(-E5-$E$9*E8) -> 0.70213738 | G10: =F10*EXP(-F5-$E$9*F8) -> 0.47339267 | H10: =G10*EXP(-G5-$E$9*G8) -> 0.3032589 | I10: =H10*EXP(-H5-$E$9*H8) -> 0.19392326 | J10: =I10*EXP(-I5-$E$9*I8) -> 0.12387826 | K10: =J10*EXP(-J5-$E$9*J8) -> 0.079148304 | L10: =K10*EXP(-K5-$E$9*K8) -> 0.050600502 | M10: =L10*EXP(-L5-$E$9*L8) -> 0.032374288 | N10: =M10*EXP(-M5-$E$9*M8) -> 0.020726549 | O10: =N10*EXP(-N5-$E$9*N8)/(1-EXP(-O5-$E$9*O8)) -> 0.036953484 | P10: - | AD10: =$E$17*AE10/(1+$E$18*AE10) -> 1812.9234 | AE10: 80
C11: Fished spawning biomass (or eggs) per recruit | D11: φF | E11: =SUMPRODUCT(E10:O10,E3:O3,E4:O4) -> 0.19060029 | P11: kg/recruit | AD11: =$E$17*AE11/(1+$E$18*AE11) -> 1925.4259 | AE11: 90
C12: Spawning potential ratio | D12: SPR | E12: =E11/E7 -> 0.68446886 | P12: - | AD12: =$E$17*AE12/(1+$E$18*AE12) -> 2026.0064 | AE12: 100
C13: Yield per recruit-at-age | D13: YPR_age | E13: =E10*E3*$E$9*E8*(1-EXP(-$E$9*E8-E5))/($E$9*E8+E5) -> 4.4331737e-05 | F13: =F10*F3*$E$9*F8*(1-EXP(-$E$9*F8-F5))/($E$9*F8+F5) -> 0.0010832509 | G13: =G10*G3*$E$9*G8*(1-EXP(-$E$9*G8-G5))/($E$9*G8+G5) -> 0.0036502598 | H13: =H10*H3*$E$9*H8*(1-EXP(-$E$9*H8-H5))/($E$9*H8+H5) -> 0.0036666328 | I13: =I10*I3*$E$9*I8*(1-EXP(-$E$9*I8-I5))/($E$9*I8+I5) -> 0.0030015311 | J13: =J10*J3*$E$9*J8*(1-EXP(-$E$9*J8-J5))/($E$9*J8+J5) -> 0.0022464741 | K13: =K10*K3*$E$9*K8*(1-EXP(-$E$9*K8-K5))/($E$9*K8+K5) -> 0.0016081968 | L13: =L10*L3*$E$9*L8*(1-EXP(-$E$9*L8-L5))/($E$9*L8+L5) -> 0.001119983 | ... O13: =O10*O3*$E$9*O8*(1-EXP(-$E$9*O8-O5))/($E$9*O8+O5) -> 0.00095324646 | P13: kg | AD13: =$E$17*AE13/(1+$E$18*AE13) -> 2116.4646 | AE13: 110
C14: Yield per recruit | D14: YPR | E14: =SUM(E13:O13) -> 0.018647642 | P14: kg | AD14: =$E$17*AE14/(1+$E$18*AE14) -> 2198.2552 | AE14: 120
C15: Equilibrium unfished recruitment | D15: R0 | E15: =3.505041*1000 -> 3505.041 | P15: 10^6 recruits | Q15: Changed units to Millions because units of weight are kg | AD15: =$E$17*AE15/(1+$E$18*AE15) -> 2272.5672 | AE15: 130
C16: Steepness | D16: h | E16: 0.75 | P16: - | Q16: User defined: model assumption | AD16: =$E$17*AE16/(1+$E$18*AE16) -> 2340.3814 | AE16: 140
C17: Beverton-Holt a | D17: a | E17: =4*E16/(E7*(1-E16)) -> 43.093461 | P17: recruit/kg | AD17: =$E$17*AE17/(1+$E$18*AE17) -> 2402.5144 | AE17: 150
C18: Beverton-Holt b | D18: b | E18: =1/E15*(E17-1/E7) -> 0.01127015 | P18: /kg | AD18: =$E$17*AE18/(1+$E$18*AE18) -> 2459.6513 | AE18: 160
C19: Equilibrium unfished SSB | D19: SSB0 | E19: =E15/(E17-E18*E15) -> 976.02956 | F19: 0 | P19: kt | Q19: Biomass units come from product of weight-at-age and units of R0 | AD19: =$E$17*AE19/(1+$E$18*AE19) -> 2512.3715 | AE19: 170
C20: Equilibrium fished recruitment | D20: Eq_recF | E20: =1/E18*(E17-1/E11) -> 3358.1521 | P20: 10^6 recruits | AD20: =$E$17*AE20/(1+$E$18*AE20) -> 2561.1681 | AE20: 180
C21: Equilibrium fished SSB | D21: Eq_SSBF | E21: =E20/(E17-E20*E18) -> 640.06478 | P21: kt | Q21: Biomass units come from product of weight-at-age and units of R | AD21: =$E$17*AE21/(1+$E$18*AE21) -> 2606.4633 | AE21: 190
C22: Yield | D22: Yield | E22: =MAX(E14*E20,0) -> 62.621619 | P22: kt | Q22: Biomass units come from product of weight-at-age and units of R | AD22: =$E$17*AE22/(1+$E$18*AE22) -> 2648.6209 | AE22: 200
AD23: =$E$17*AE23/(1+$E$18*AE23) -> 2687.9561 | AE23: 210
C24: Beverton-Holt SRR (parameterized in terms of a and b): | AD24: =$E$17*AE24/(1+$E$18*AE24) -> 2724.7431 | AE24: 220
AD25: =$E$17*AE25/(1+$E$18*AE25) -> 2759.2218 | AE25: 230
AD26: =$E$17*AE26/(1+$E$18*AE26) -> 2791.6028 | AE26: 240
AD27: =$E$17*AE27/(1+$E$18*AE27) -> 2822.0718 | AE27: 250
C28: Beverton-Holt SRR (parameterized in terms of h and R0): | AD28: =$E$17*AE28/(1+$E$18*AE28) -> 2850.7934 | AE28: 260
AD29: =$E$17*AE29/(1+$E$18*AE29) -> 2877.9138 | AE29: 270
AD30: =$E$17*AE30/(1+$E$18*AE30) -> 2903.5631 | AE30: 280
AD31: =$E$17*AE31/(1+$E$18*AE31) -> 2927.8579 | AE31: 290
F32: Note: h depends on φ0 (the equilibrium unfished spawning biomass per recruit). The term "equilibrium" is key because φ0 depends on weight-at-age, maturity-at-age, and M | AD32: =$E$17*AE32/(1+$E$18*AE32) -> 2950.9028 | AE32: 300
F33: A B-H SRR parameterized using h and R0 and be reparmeterized in terms of a and b assuming an equilibrium unfished spawning biomass per recruit (φ0) | AD33: =$E$17*AE33/(1+$E$18*AE33) -> 2972.7918 | AE33: 310
F34: See Miller and Brooks (2021) for more details | AD34: =$E$17*AE34/(1+$E$18*AE34) -> 2993.6096 | AE34: 320
F35: https://onlinelibrary.wiley.com/doi/full/10.1111/faf.12534 | AD35: =$E$17*AE35/(1+$E$18*AE35) -> 3013.4332 | AE35: 330
AD36: =$E$17*AE36/(1+$E$18*AE36) -> 3032.332 | AE36: 340
AD37: =$E$17*AE37/(1+$E$18*AE37) -> 3050.3693 | AE37: 350
AD38: =$E$17*AE38/(1+$E$18*AE38) -> 3067.6026 | AE38: 360
AD39: =$E$17*AE39/(1+$E$18*AE39) -> 3084.0846 | AE39: 370
AD40: =$E$17*AE40/(1+$E$18*AE40) -> 3099.8633 | AE40: 380
...

Sheet MSY
A1: 6. Define SRR from steepness (h) and equilibrium unfished recruitment (R0) | AD1: Recruitment (10^9) | AE1: SSB (kt)
C2: Parameter | E2: 1 | F2: 2 | G2: 3 | H2: 4 | I2: 5 | J2: 6 | K2: 7 | L2: 8 | M2: 9 | N2: 10 | O2: 11+ | P2: units | Q2: Comments | AD2: =$E$17*AE2/(1+$E$18*AE2) -> 4.3044949 | AE2: 0.1
C3: Weight-at-age | D3: w_age | E3: 0.014514176 | F3: 0.042231692 | G3: 0.10022034 | H3: 0.15438523 | I3: 0.19563793 | J3: 0.22963509 | K3: 0.25884311 | L3: 0.28409739 | M3: 0.3044291 | N3: 0.31988238 | O3: 0.33599304 | P3: kg | Q3: User defined: estimated from biological sampling | AD3: =$E$17*AE3/(1+$E$18*AE3) -> 387.2868 | AE3: 10
C4: Proportion mature | D4: m_age | E4: 0.0054683992 | F4: 0.036348653 | G4: 0.39111466 | H4: 0.88567802 | I4: 0.98410829 | J4: 0.99653237 | K4: 0.99897673 | L4: 0.99966407 | M4: 0.99988525 | N4: 0.99996004 | O4: 0.99998593 | P4: - | Q4: User defined: estimated from biological sampling | AD4: =$E$17*AE4/(1+$E$18*AE4) -> 703.33532 | AE4: 20
A5: Start with F = | B5: 0.1 | C5: M | D5: M_age | E5: 0.35 | F5: 0.35 | G5: 0.35 | H5: 0.35 | I5: 0.35 | J5: 0.35 | K5: 0.35 | L5: 0.35 | M5: 0.35 | N5: 0.35 | O5: 0.35 | P5: - | Q5: User defined: model assumption | AD5: =$E$17*AE5/(1+$E$18*AE5) -> 966.14563 | AE5: 30
C6: Unfished survivorship | D6: l0_age | E6: 1 | F6: =E6*EXP(-E5) -> 0.70468809 | G6: =F6*EXP(-F5) -> 0.4965853 | H6: =G6*EXP(-G5) -> 0.34993775 | I6: =H6*EXP(-H5) -> 0.24659696 | J6: =I6*EXP(-I5) -> 0.17377394 | K6: =J6*EXP(-J5) -> 0.12245643 | L6: =K6*EXP(-K5) -> 0.086293586 | M6: =L6*EXP(-L5) -> 0.060810063 | N6: =M6*EXP(-M5) -> 0.042852127 | O6: =N6*EXP(-N5)/(1-EXP(-O5)) -> 0.10225589 | P6: - | Q6: unfished so use F=0 | AD6: =$E$17*AE6/(1+$E$18*AE6) -> 1188.1247 | AE6: 40
C7: Unfished spawning biomass (or eggs) per recruit | D7: φ0 | E7: =SUMPRODUCT(E6:O6,E3:O3,E4:O4) -> 0.27846452 | P7: kg/recruit | AD7: =$E$17*AE7/(1+$E$18*AE7) -> 1378.1021 | AE7: 50
C8: Vulnerability (selectivity) | D8: v_age | E8: 0.036261919 | F8: 0.44203881 | G8: 0.95338308 | H8: 0.97124384 | I8: 0.98163231 | J8: 0.97975931 | K8: 0.97361862 | L8: 0.96596968 | M8: 0.95949061 | N8: 0.95474833 | O8: 0.95125692 | P8: - | Q8: User defined: Model output | AD8: =$E$17*AE8/(1+$E$18*AE8) -> 1542.533 | AE8: 60
A9: 7. Calculate equilbrium fished recruitment and equilibrium fished SSB | C9: Fishing mortality rate | D9: F | E9: =B5 -> 0.1 | P9: - | AD9: =$E$17*AE9/(1+$E$18*AE9) -> 1686.2455 | AE9: 70
C10: Fished survivorship | D10: lF_age | E10: 1 | F10: =E10*EXP(-E5-$E$9*E8) -> 0.70213738 | G10: =F10*EXP(-F5-$E$9*F8) -> 0.47339267 | H10: =G10*EXP(-G5-$E$9*G8) -> 0.3032589 | I10: =H10*EXP(-H5-$E$9*H8) -> 0.19392326 | J10: =I10*EXP(-I5-$E$9*I8) -> 0.12387826 | K10: =J10*EXP(-J5-$E$9*J8) -> 0.079148304 | L10: =K10*EXP(-K5-$E$9*K8) -> 0.050600502 | M10: =L10*EXP(-L5-$E$9*L8) -> 0.032374288 | N10: =M10*EXP(-M5-$E$9*M8) -> 0.020726549 | O10: =N10*EXP(-N5-$E$9*N8)/(1-EXP(-O5-$E$9*O8)) -> 0.036953484 | P10: - | AD10: =$E$17*AE10/(1+$E$18*AE10) -> 1812.9234 | AE10: 80
C11: Fished spawning biomass (or eggs) per recruit | D11: φF | E11: =SUMPRODUCT(E10:O10,E3:O3,E4:O4) -> 0.19060029 | P11: kg/recruit | AD11: =$E$17*AE11/(1+$E$18*AE11) -> 1925.4259 | AE11: 90
C12: Spawning potential ratio | D12: SPR | E12: =E11/E7 -> 0.68446886 | P12: - | AD12: =$E$17*AE12/(1+$E$18*AE12) -> 2026.0064 | AE12: 100
C13: Yield per recruit-at-age | D13: YPR_age | E13: =E10*E3*$E$9*E8*(1-EXP(-$E$9*E8-E5))/($E$9*E8+E5) -> 4.4331737e-05 | F13: =F10*F3*$E$9*F8*(1-EXP(-$E$9*F8-F5))/($E$9*F8+F5) -> 0.0010832509 | G13: =G10*G3*$E$9*G8*(1-EXP(-$E$9*G8-G5))/($E$9*G8+G5) -> 0.0036502598 | H13: =H10*H3*$E$9*H8*(1-EXP(-$E$9*H8-H5))/($E$9*H8+H5) -> 0.0036666328 | I13: =I10*I3*$E$9*I8*(1-EXP(-$E$9*I8-I5))/($E$9*I8+I5) -> 0.0030015311 | J13: =J10*J3*$E$9*J8*(1-EXP(-$E$9*J8-J5))/($E$9*J8+J5) -> 0.0022464741 | K13: =K10*K3*$E$9*K8*(1-EXP(-$E$9*K8-K5))/($E$9*K8+K5) -> 0.0016081968 | L13: =L10*L3*$E$9*L8*(1-EXP(-$E$9*L8-L5))/($E$9*L8+L5) -> 0.001119983 | ... O13: =O10*O3*$E$9*O8*(1-EXP(-$E$9*O8-O5))/($E$9*O8+O5) -> 0.00095324646 | P13: kg | AD13: =$E$17*AE13/(1+$E$18*AE13) -> 2116.4646 | AE13: 110
C14: Yield per recruit | D14: YPR | E14: =SUM(E13:O13) -> 0.018647642 | P14: kg | AD14: =$E$17*AE14/(1+$E$18*AE14) -> 2198.2552 | AE14: 120
C15: Equilibrium unfished recruitment | D15: R0 | E15: =3.505041*1000 -> 3505.041 | P15: 10^6 recruits | Q15: User defined: Model output | AD15: =$E$17*AE15/(1+$E$18*AE15) -> 2272.5672 | AE15: 130
C16: Steepness | D16: h | E16: 0.75 | P16: - | Q16: User defined: model assumption | AD16: =$E$17*AE16/(1+$E$18*AE16) -> 2340.3814 | AE16: 140
C17: Beverton-Holt a | D17: a | E17: =4*E16/(E7*(1-E16)) -> 43.093461 | P17: recruit/kg | AD17: =$E$17*AE17/(1+$E$18*AE17) -> 2402.5144 | AE17: 150
C18: Beverton-Holt b | D18: b | E18: =1/E15*(E17-1/E7) -> 0.01127015 | P18: /kg | AD18: =$E$17*AE18/(1+$E$18*AE18) -> 2459.6513 | AE18: 160
C19: Equilibrium unfished SSB | D19: SSB0 | E19: =E15/(E17-E18*E15) -> 976.02956 | F19: 0 | P19: kt | AD19: =$E$17*AE19/(1+$E$18*AE19) -> 2512.3715 | AE19: 170
C20: Equilibrium fished recruitment | D20: Eq_recF | E20: =1/E18*(E17-1/E11) -> 3358.1521 | P20: 10^6 recruits | AD20: =$E$17*AE20/(1+$E$18*AE20) -> 2561.1681 | AE20: 180
C21: Equilibrium fished SSB | D21: Eq_SSBF | E21: =E20/(E17-E20*E18) -> 640.06478 | P21: kt | AD21: =$E$17*AE21/(1+$E$18*AE21) -> 2606.4633 | AE21: 190
C22: Yield | D22: Yield | E22: =MAX(E14*E20,0) -> 62.621619 | P22: kt | AD22: =$E$17*AE22/(1+$E$18*AE22) -> 2648.6209 | AE22: 200
AD23: =$E$17*AE23/(1+$E$18*AE23) -> 2687.9561 | AE23: 210
A24: 8. Add what-if analysis to calculate Yield for various F and estimate equilibrium MSY reference points | C24: Fishing mortality at MSY | D24: FMSY | E24: =VLOOKUP(E25,G43:M544,7,FALSE) -> 0.34 | P24: - | Q24: F corresponding to max yield | AD24: =$E$17*AE24/(1+$E$18*AE24) -> 2724.7431 | AE24: 220
C25: MSY | D25: MSY | E25: =MAX(G43:G294) -> 97.321997 | P25: kt | Q25: Max yield from what-if analysis table | AD25: =$E$17*AE25/(1+$E$18*AE25) -> 2759.2218 | AE25: 230
C26: Equilibrium SSBMSY | D26: SSBMSY | E26: =VLOOKUP(E24,A43:F544,6,FALSE) -> 279.96185 | P26: kt | Q26: Equilibrium SSB from fishing at Fmsy | AD26: =$E$17*AE26/(1+$E$18*AE26) -> 2791.6028 | AE26: 240
AD27: =$E$17*AE27/(1+$E$18*AE27) -> 2822.0718 | AE27: 250
AD28: =$E$17*AE28/(1+$E$18*AE28) -> 2850.7934 | AE28: 260
AD29: =$E$17*AE29/(1+$E$18*AE29) -> 2877.9138 | AE29: 270
AD30: =$E$17*AE30/(1+$E$18*AE30) -> 2903.5631 | AE30: 280
AD31: =$E$17*AE31/(1+$E$18*AE31) -> 2927.8579 | AE31: 290
AD32: =$E$17*AE32/(1+$E$18*AE32) -> 2950.9028 | AE32: 300
AD33: =$E$17*AE33/(1+$E$18*AE33) -> 2972.7918 | AE33: 310
AD34: =$E$17*AE34/(1+$E$18*AE34) -> 2993.6096 | AE34: 320
AD35: =$E$17*AE35/(1+$E$18*AE35) -> 3013.4332 | AE35: 330
AD36: =$E$17*AE36/(1+$E$18*AE36) -> 3032.332 | AE36: 340
AD37: =$E$17*AE37/(1+$E$18*AE37) -> 3050.3693 | AE37: 350
AD38: =$E$17*AE38/(1+$E$18*AE38) -> 3067.6026 | AE38: 360
... AD40: =$E$17*AE40/(1+$E$18*AE40) -> 3099.8633 | AE40: 380
A41: What if analysis for different F | AD41: =$E$17*AE41/(1+$E$18*AE41) -> 3114.9829 | AE41: 390
...

Sheet Solution
B1: Metric | C1: Value | D1: Units
A2: 1 | B2: Equilibrium SSBMSY | C2: =MSY!E26 -> 279.96185 | D2: kt
A3: 2 | B3: Equilibrium SSB0 | C3: =MSY!E19 -> 976.02956 | D3: kt
A4: 3 | B4: Equilibrium SSB at F40% (assuming no stock recruitment relationship) | C4: ='SSB at SPRx'!E27 -> 392.07522 | D4: kt
A5: 4 | B5: SSB at 50% R0 (from stock recruitment relationship) | C5: =G9/(G10-G11*G9) -> 75.079197 | D5: kt
F9: 50% R0 | G9: =MSY!E15/2 -> 1752.5205
F10: Bha | G10: =MSY!E17 -> 43.093461
F11: BHb | G11: =MSY!E18 -> 0.01127015
