Workbook

Sheet Read Me
A1: This spreadsheet guides you through some reference point calculations using an example data set with ages 1 to 9+
A2: The example data set is for a haddock stock but the calculations are not species specific and the number of age classes can be modified
A3: Some example plots can be found on the last 2 tabs
A5: Tab | B5: Inputs | C5: Outputs
A6: phi0 | B6: weight-, maturity-, and natural mortality-at-age | C6: Unfished spawning biomass per recruit (φ0)
A7: phiF SPR YPR | B7: weight-, maturity-, vulnerability- and natural mortality-at-age | C7: Fished spawning biomass per recruit (φF)
B8: F | C8: Spawning Potential Ratio (SPR)
C9: Yield per Recruit (YPR)
A10: SPR YPR all F | B10: weight-, maturity-, vulnerability- and natural mortality-at-age
B11: calculations over a range of F values
A12: Fx%SPR | B12: weight-, maturity-, vulnerability- and natural mortality-at-age | C12: FX% (i.e. F at X% SPR)
B13: calculations over a range of F values
B14: X corresponding to X% SPR
A15: SSB at Fx%SPR | B15: weight-, maturity-, vulnerability- and natural mortality-at-age | C15: Equilibrium SSB at FX% (i.e. F at X% SPR)
B16: calculations over a range of F values | C16: Equilibrium unfished spawning biomass (SSB0)
B17: X corresponding to X% SPR
B18: Equilibrium unfished recruitment
A19: Add stock recruitment relationship
A20: SRR and Yield | B20: weight-, maturity-, vulnerability- and natural mortality-at-age | C20: Equilibrium unfished spawning biomass (SSB0)
B21: steepness and equilibrium unfished recuitment OR Beverton-Holt a and b | C21: Equilibrium recruitment at F=F
B22: F | C22: Equilibrium spawning biomass at F=F
C23: Yield at F=F
A24: MSY | B24: weight-, maturity-, vulnerability- and natural mortality-at-age | C24: Equilibrium MSY, FMSY, SSBMSY
B25: steepness and equilibrium unfished recuitment OR Beverton-Holt a and b
B26: calculations over a range of F values
A29: Legend for shading:
A30: User defined value (value, biological data, or model output)
A31: Estimated for F=0 (unfished)
A32: Estimated for F=F (fished)
A33: Note difference in formula when dragging cells across (first age class and plus group)
A34: No stock recruitment relationship assumed

Sheet phi0
A1: 1. Calculate unfished spawning biomass per recruit (φ0) | E1: At-age - Biological Data (estimated)
C2: Parameter | E2: 1 | F2: 2 | G2: 3 | H2: 4 | I2: 5 | J2: 6 | K2: 7 | L2: 8 | M2: 9+ | N2: units | O2: Comments
C3: Weight-at-age | D3: w_age | E3: 0.5286875 | F3: 0.9174375 | G3: 1.2655 | H3: 1.6353958 | I3: 1.9437292 | J3: 2.2155417 | K3: 2.5180417 | L3: 2.7956042 | M3: 3.1556875 | N3: kg | O3: User defined: estimated from biological sampling
C4: Proportion mature | D4: m_age | E4: 0.18988256 | F4: 0.51525951 | G4: 0.83071832 | H4: 0.94003788 | I4: 0.97565145 | J4: 0.98904096 | K4: 0.99470052 | L4: 0.9973005 | M4: 0.99856954 | N4: - | O4: User defined: estimated from biological sampling
C5: M | D5: M | E5: 0.2 | F5: =E5 -> 0.2 | G5: =F5 -> 0.2 | H5: =G5 -> 0.2 | I5: =H5 -> 0.2 | J5: =I5 -> 0.2 | K5: =J5 -> 0.2 | L5: =K5 -> 0.2 | M5: =L5 -> 0.2 | N5: - | O5: User defined: model assumption
C6: Unfished survivorship | D6: l0_age | E6: 1 | F6: =E6*EXP(-E5) -> 0.81873075 | G6: =F6*EXP(-F5) -> 0.67032005 | H6: =G6*EXP(-G5) -> 0.54881164 | I6: =H6*EXP(-H5) -> 0.44932896 | J6: =I6*EXP(-I5) -> 0.36787944 | K6: =J6*EXP(-J5) -> 0.30119421 | L6: =K6*EXP(-K5) -> 0.24659696 | M6: =L6*EXP(-L5)/(1-EXP(-M5)) -> 1.1137935 | N6: - | O6: unfished so use F=0 in formulas below
B7: 1 | C7: Unfished spawning biomass (or eggs) per recruit | D7: φ0 | E7: =SUMPRODUCT(E6:M6,E3:M3,E4:M4) -> 8.6457264 | N7: kg/recruit
C14: Equations
C16: Equilibrium survivorship-at-age: | I16: va = vulnerability-at-age
C21: Equilibrium spawning biomass per recruit:
C25: Note: If fecundity data are available, use equilibrium eggs per recruit. A common assumption is fecundity is proportional to spawning biomass.
C27: Equilibrium eggs per recruit: | G27: fa = relative fecundity (eggs per units mass)

Sheet phiF SPR YPR
A1: 2. Calculate spawning biomass per recruit (φF), spawning potential ratio (SPR), and yield per recruit (YPR) for a specified F (e.g. F = 0.1)
C2: Parameter | E2: 1 | F2: 2 | G2: 3 | H2: 4 | I2: 5 | J2: 6 | K2: 7 | L2: 8 | M2: 9+ | N2: units | O2: Comments
C3: Weight-at-age | D3: w_age | E3: =phi0!E3 -> 0.5286875 | F3: =phi0!F3 -> 0.9174375 | G3: =phi0!G3 -> 1.2655 | H3: =phi0!H3 -> 1.6353958 | I3: =phi0!I3 -> 1.9437292 | J3: =phi0!J3 -> 2.2155417 | K3: =phi0!K3 -> 2.5180417 | L3: =phi0!L3 -> 2.7956042 | M3: =phi0!M3 -> 3.1556875 | N3: kg | O3: User defined: estimated from biological sampling
C4: Proportion mature | D4: m_age | E4: =phi0!E4 -> 0.18988256 | F4: =phi0!F4 -> 0.51525951 | G4: =phi0!G4 -> 0.83071832 | H4: =phi0!H4 -> 0.94003788 | I4: =phi0!I4 -> 0.97565145 | J4: =phi0!J4 -> 0.98904096 | K4: =phi0!K4 -> 0.99470052 | L4: =phi0!L4 -> 0.9973005 | M4: =phi0!M4 -> 0.99856954 | N4: - | O4: User defined: estimated from biological sampling
C5: M | D5: M_age | E5: =phi0!E5 -> 0.2 | F5: =E5 -> 0.2 | G5: =F5 -> 0.2 | H5: =G5 -> 0.2 | I5: =H5 -> 0.2 | J5: =I5 -> 0.2 | K5: =J5 -> 0.2 | L5: =K5 -> 0.2 | M5: =L5 -> 0.2 | N5: - | O5: User defined: model assumption
A6: Start with F = | B6: 0.1 | C6: Unfished survivorship | D6: l0_age | E6: 1 | F6: =E6*EXP(-E5) -> 0.81873075 | G6: =F6*EXP(-F5) -> 0.67032005 | H6: =G6*EXP(-G5) -> 0.54881164 | I6: =H6*EXP(-H5) -> 0.44932896 | J6: =I6*EXP(-I5) -> 0.36787944 | K6: =J6*EXP(-J5) -> 0.30119421 | L6: =K6*EXP(-K5) -> 0.24659696 | M6: =L6*EXP(-L5)/(1-EXP(-M5)) -> 1.1137935 | N6: - | O6: unfished so use F=0
C7: Unfished spawning biomass (or eggs) per recruit | D7: φ0 | E7: =SUMPRODUCT(E6:M6,E3:M3,E4:M4) -> 8.6457264 | N7: kg/recruit
C8: Vulnerability (selectivity) | D8: v_age | E8: 0.004043636 | F8: 0.048546621 | G8: 0.35489582 | H8: 0.72466873 | I8: 0.90894167 | J8: 0.97144024 | K8: 0.98972695 | L8: 0.99659089 | M8: 0.99806452 | N8: - | O8: User defined: Model output
C9: Fishing mortality rate | D9: F | E9: =B6 -> 0.1 | N9: -
C10: Fished survivorship | D10: lF_age | E10: 1 | F10: =E10*EXP(-E5-$E$9*E8) -> 0.81839976 | G10: =F10*EXP(-F5-$E$9*F8) -> 0.66680407 | H10: =G10*EXP(-G5-$E$9*G8) -> 0.52689784 | I10: =H10*EXP(-H5-$E$9*H8) -> 0.40123199 | J10: =I10*EXP(-I5-$E$9*I8) -> 0.29995895 | K10: =J10*EXP(-J5-$E$9*J8) -> 0.2228506 | L10: =K10*EXP(-K5-$E$9*K8) -> 0.16526147 | M10: =L10*EXP(-L5-$E$9*L8)/(1-EXP(-M5-$E$9*M8)) -> 0.47278884 | N10: -
B11: 2 | C11: Fished spawning biomass (or eggs) per recruit | D11: φF | E11: =SUMPRODUCT(E10:M10,E3:M3,E4:M4) -> 5.9252301 | N11: kg/recruit
B12: 2 | C12: Spawning potential ratio | D12: SPR | E12: =E11/E7 -> 0.68533629 | N12: -
C13: Yield per recruit-at-age | D13: YPR_age | E13: =E10*E3*$E$9*E8*(1-EXP(-$E$9*E8-E5))/($E$9*E8+E5) -> 0.00019372263 | F13: =F10*F3*$E$9*F8*(1-EXP(-$E$9*F8-F5))/($E$9*F8+F5) -> 0.0032959187 | G13: =G10*G3*$E$9*G8*(1-EXP(-$E$9*G8-G5))/($E$9*G8+G5) -> 0.026682616 | H13: =H10*H3*$E$9*H8*(1-EXP(-$E$9*H8-H5))/($E$9*H8+H5) -> 0.054659537 | I13: =I10*I3*$E$9*I8*(1-EXP(-$E$9*I8-I5))/($E$9*I8+I5) -> 0.06150786 | J13: =J10*J3*$E$9*J8*(1-EXP(-$E$9*J8-J5))/($E$9*J8+J5) -> 0.055850929 | K13: =K10*K3*$E$9*K8*(1-EXP(-$E$9*K8-K5))/($E$9*K8+K5) -> 0.048005091 | L13: =L10*L3*$E$9*L8*(1-EXP(-$E$9*L8-L5))/($E$9*L8+L5) -> 0.039784853 | M13: =M10*M3*$E$9*M8*(1-EXP(-$E$9*M8-M5))/($E$9*M8+M5) -> 0.12865983 | N13: kg
B14: 2 | C14: Yield per recruit | D14: YPR | E14: =SUM(E13:M13) -> 0.41864035 | N14: kg
C24: Equations
C26: Equilibrium survivorship-at-age: | I26: va = vulnerability-at-age
C31: Equilibrium spawning biomass per recruit:
C34: Spawning Potential Ratio: | F34: Ratio of (spawning biomass per recruit in the fished state) to (spawning biomass per recruit in the unfished state)
C37: Yield Per Recruit :

Sheet SPR YPR all F
A1: 3. Calculate SPR and YPR over a range of F values. This is done using a What-If Analysis Data Table in Excel
C2: Parameter | E2: 1 | F2: 2 | G2: 3 | H2: 4 | I2: 5 | J2: 6 | K2: 7 | L2: 8 | M2: 9+ | N2: units | O2: Comments
C3: Weight-at-age | D3: w_age | E3: =phi0!E3 -> 0.5286875 | F3: =phi0!F3 -> 0.9174375 | G3: =phi0!G3 -> 1.2655 | H3: =phi0!H3 -> 1.6353958 | I3: =phi0!I3 -> 1.9437292 | J3: =phi0!J3 -> 2.2155417 | K3: =phi0!K3 -> 2.5180417 | L3: =phi0!L3 -> 2.7956042 | M3: =phi0!M3 -> 3.1556875 | N3: kg | O3: User defined: estimated from biological sampling
C4: Proportion mature | D4: m_age | E4: =phi0!E4 -> 0.18988256 | F4: =phi0!F4 -> 0.51525951 | G4: =phi0!G4 -> 0.83071832 | H4: =phi0!H4 -> 0.94003788 | I4: =phi0!I4 -> 0.97565145 | J4: =phi0!J4 -> 0.98904096 | K4: =phi0!K4 -> 0.99470052 | L4: =phi0!L4 -> 0.9973005 | M4: =phi0!M4 -> 0.99856954 | N4: - | O4: User defined: estimated from biological sampling
C5: M | D5: M_age | E5: =phi0!E5 -> 0.2 | F5: =E5 -> 0.2 | G5: =F5 -> 0.2 | H5: =G5 -> 0.2 | I5: =H5 -> 0.2 | J5: =I5 -> 0.2 | K5: =J5 -> 0.2 | L5: =K5 -> 0.2 | M5: =L5 -> 0.2 | N5: - | O5: User defined: model assumption
A6: Start with F = | B6: 0.1 | C6: Unfished survivorship | D6: l0_age | E6: 1 | F6: =E6*EXP(-E5) -> 0.81873075 | G6: =F6*EXP(-F5) -> 0.67032005 | H6: =G6*EXP(-G5) -> 0.54881164 | I6: =H6*EXP(-H5) -> 0.44932896 | J6: =I6*EXP(-I5) -> 0.36787944 | K6: =J6*EXP(-J5) -> 0.30119421 | L6: =K6*EXP(-K5) -> 0.24659696 | M6: =L6*EXP(-L5)/(1-EXP(-M5)) -> 1.1137935 | N6: - | O6: unfished so use F=0
C7: Unfished spawning biomass (or eggs) per recruit | D7: φ0 | E7: =SUMPRODUCT(E6:M6,E3:M3,E4:M4) -> 8.6457264 | N7: kg/recruit
C8: Vulnerability (selectivity) | D8: v_age | E8: ='phiF SPR YPR'!E8 -> 0.004043636 | F8: ='phiF SPR YPR'!F8 -> 0.048546621 | G8: ='phiF SPR YPR'!G8 -> 0.35489582 | H8: ='phiF SPR YPR'!H8 -> 0.72466873 | I8: ='phiF SPR YPR'!I8 -> 0.90894167 | J8: ='phiF SPR YPR'!J8 -> 0.97144024 | K8: ='phiF SPR YPR'!K8 -> 0.98972695 | L8: ='phiF SPR YPR'!L8 -> 0.99659089 | M8: ='phiF SPR YPR'!M8 -> 0.99806452 | N8: - | O8: User defined: Model output
C9: Fishing mortality rate | D9: F | E9: =B6 -> 0.1 | N9: -
C10: Fished survivorship | D10: lF_age | E10: 1 | F10: =E10*EXP(-E5-$E$9*E8) -> 0.81839976 | G10: =F10*EXP(-F5-$E$9*F8) -> 0.66680407 | H10: =G10*EXP(-G5-$E$9*G8) -> 0.52689784 | I10: =H10*EXP(-H5-$E$9*H8) -> 0.40123199 | J10: =I10*EXP(-I5-$E$9*I8) -> 0.29995895 | K10: =J10*EXP(-J5-$E$9*J8) -> 0.2228506 | L10: =K10*EXP(-K5-$E$9*K8) -> 0.16526147 | M10: =L10*EXP(-L5-$E$9*L8)/(1-EXP(-M5-$E$9*M8)) -> 0.47278884 | N10: -
C11: Fished spawning biomass (or eggs) per recruit | D11: φF | E11: =SUMPRODUCT(E10:M10,E3:M3,E4:M4) -> 5.9252301 | N11: kg/recruit
C12: Spawning potential ratio | D12: SPR | E12: =E11/E7 -> 0.68533629 | N12: -
C13: Yield per recruit-at-age | D13: YPR_age | E13: =E10*E3*$E$9*E8*(1-EXP(-$E$9*E8-E5))/($E$9*E8+E5) -> 0.00019372263 | F13: =F10*F3*$E$9*F8*(1-EXP(-$E$9*F8-F5))/($E$9*F8+F5) -> 0.0032959187 | G13: =G10*G3*$E$9*G8*(1-EXP(-$E$9*G8-G5))/($E$9*G8+G5) -> 0.026682616 | H13: =H10*H3*$E$9*H8*(1-EXP(-$E$9*H8-H5))/($E$9*H8+H5) -> 0.054659537 | I13: =I10*I3*$E$9*I8*(1-EXP(-$E$9*I8-I5))/($E$9*I8+I5) -> 0.06150786 | J13: =J10*J3*$E$9*J8*(1-EXP(-$E$9*J8-J5))/($E$9*J8+J5) -> 0.055850929 | K13: =K10*K3*$E$9*K8*(1-EXP(-$E$9*K8-K5))/($E$9*K8+K5) -> 0.048005091 | L13: =L10*L3*$E$9*L8*(1-EXP(-$E$9*L8-L5))/($E$9*L8+L5) -> 0.039784853 | M13: =M10*M3*$E$9*M8*(1-EXP(-$E$9*M8-M5))/($E$9*M8+M5) -> 0.12865983 | N13: kg
C14: Yield per recruit | D14: YPR | E14: =SUM(E13:M13) -> 0.41864035 | N14: kg
B17: 3 | C17: Step 1. Define Column Headers (F, SPR, YPR) in row 27.
C18: Step 2. In the first row enter SPR and YPR from the example above for F = 0.1 (i.e. cell B29=D12, cell C29 = E14)
C19: Step 3. Generate a column of F values (cells A30-A280)
C20: Step 4. Highlight cells A29-C280 and select Data: What-if-analysis: Data Table
C21: Step 5. In the Data Table window - enter cell $B$6 which is F
C22: Step 6. Click OK
C23: The Data Table now provides SPR and YPR for each F
C24: Step 7. Plot SPR and YPR relative to F
A27: What-If Analysis Data Table to calculate SPR and YPR for various F
A28: F | B28: SPR | C28: YPR
B29: =E12 -> 0.68533629 | C29: =E14 -> 0.41864035
A30: 0.0001 | B30: 0.99952159 | C30: 0.00068128969
A31: 0.01 | B31: 0.9544842 | C31: 0.064334346
A32: 0.02 | B32: 0.91323766 | C32: 0.12173193
A33: 0.03 | B33: 0.87569914 | C33: 0.17314724
A34: 0.04 | B34: 0.84140099 | C34: 0.21937346
A35: 0.05 | B35: 0.80995045 | C35: 0.26107473
A36: 0.06 | B36: 0.78101526 | C36: 0.29881111
A37: 0.07 | B37: 0.75431248 | C37: 0.33305789
A38: 0.08 | B38: 0.72959967 | C38: 0.36422082
A39: 0.09 | B39: 0.70666793 | C39: 0.39264817
A40: 0.1 | B40: 0.68533629 | C40: 0.41864035
A41: 0.11 | B41: 0.66544723 | C41: 0.44245775
... A280: 2.5 | B280: 0.16905811 | C280: 0.78511485

Sheet Fx%SPR
A1: 4. Calculate FX% (i.e. F at X% SPR)
C2: Parameter | E2: 1 | F2: 2 | G2: 3 | H2: 4 | I2: 5 | J2: 6 | K2: 7 | L2: 8 | M2: 9+ | N2: units | O2: Comments
C3: Weight-at-age | D3: w_age | E3: =phi0!E3 -> 0.5286875 | F3: =phi0!F3 -> 0.9174375 | G3: =phi0!G3 -> 1.2655 | H3: =phi0!H3 -> 1.6353958 | I3: =phi0!I3 -> 1.9437292 | J3: =phi0!J3 -> 2.2155417 | K3: =phi0!K3 -> 2.5180417 | L3: =phi0!L3 -> 2.7956042 | M3: =phi0!M3 -> 3.1556875 | N3: kg | O3: User defined: estimated from biological sampling
C4: Proportion mature | D4: m_age | E4: =phi0!E4 -> 0.18988256 | F4: =phi0!F4 -> 0.51525951 | G4: =phi0!G4 -> 0.83071832 | H4: =phi0!H4 -> 0.94003788 | I4: =phi0!I4 -> 0.97565145 | J4: =phi0!J4 -> 0.98904096 | K4: =phi0!K4 -> 0.99470052 | L4: =phi0!L4 -> 0.9973005 | M4: =phi0!M4 -> 0.99856954 | N4: - | O4: User defined: estimated from biological sampling
C5: M | D5: M_age | E5: =phi0!E5 -> 0.2 | F5: =E5 -> 0.2 | G5: =F5 -> 0.2 | H5: =G5 -> 0.2 | I5: =H5 -> 0.2 | J5: =I5 -> 0.2 | K5: =J5 -> 0.2 | L5: =K5 -> 0.2 | M5: =L5 -> 0.2 | N5: - | O5: User defined: model assumption
A6: Start with F = | B6: 0.1 | C6: Unfished survivorship | D6: l0_age | E6: 1 | F6: =E6*EXP(-E5) -> 0.81873075 | G6: =F6*EXP(-F5) -> 0.67032005 | H6: =G6*EXP(-G5) -> 0.54881164 | I6: =H6*EXP(-H5) -> 0.44932896 | J6: =I6*EXP(-I5) -> 0.36787944 | K6: =J6*EXP(-J5) -> 0.30119421 | L6: =K6*EXP(-K5) -> 0.24659696 | M6: =L6*EXP(-L5)/(1-EXP(-M5)) -> 1.1137935 | N6: - | O6: unfished so use F=0
C7: Unfished spawning biomass (or eggs) per recruit | D7: φ0 | E7: =SUMPRODUCT(E6:M6,E3:M3,E4:M4) -> 8.6457264 | N7: kg/recruit
C8: Vulnerability (selectivity) | D8: v_age | E8: ='phiF SPR YPR'!E8 -> 0.004043636 | F8: ='phiF SPR YPR'!F8 -> 0.048546621 | G8: ='phiF SPR YPR'!G8 -> 0.35489582 | H8: ='phiF SPR YPR'!H8 -> 0.72466873 | I8: ='phiF SPR YPR'!I8 -> 0.90894167 | J8: ='phiF SPR YPR'!J8 -> 0.97144024 | K8: ='phiF SPR YPR'!K8 -> 0.98972695 | L8: ='phiF SPR YPR'!L8 -> 0.99659089 | M8: ='phiF SPR YPR'!M8 -> 0.99806452 | N8: - | O8: User defined: Model output
C9: Fishing mortality rate | D9: F | E9: =B6 -> 0.1 | N9: -
C10: Fished survivorship | D10: lF_age | E10: 1 | F10: =E10*EXP(-E5-$E$9*E8) -> 0.81839976 | G10: =F10*EXP(-F5-$E$9*F8) -> 0.66680407 | H10: =G10*EXP(-G5-$E$9*G8) -> 0.52689784 | I10: =H10*EXP(-H5-$E$9*H8) -> 0.40123199 | J10: =I10*EXP(-I5-$E$9*I8) -> 0.29995895 | K10: =J10*EXP(-J5-$E$9*J8) -> 0.2228506 | L10: =K10*EXP(-K5-$E$9*K8) -> 0.16526147 | M10: =L10*EXP(-L5-$E$9*L8)/(1-EXP(-M5-$E$9*M8)) -> 0.47278884 | N10: -
C11: Fished spawning biomass (or eggs) per recruit | D11: φF | E11: =SUMPRODUCT(E10:M10,E3:M3,E4:M4) -> 5.9252301 | N11: kg/recruit
C12: Spawning potential ratio | D12: SPR | E12: =E11/E7 -> 0.68533629 | N12: -
C13: Yield per recruit-at-age | D13: YPR_age | E13: =E10*E3*$E$9*E8*(1-EXP(-$E$9*E8-E5))/($E$9*E8+E5) -> 0.00019372263 | F13: =F10*F3*$E$9*F8*(1-EXP(-$E$9*F8-F5))/($E$9*F8+F5) -> 0.0032959187 | G13: =G10*G3*$E$9*G8*(1-EXP(-$E$9*G8-G5))/($E$9*G8+G5) -> 0.026682616 | H13: =H10*H3*$E$9*H8*(1-EXP(-$E$9*H8-H5))/($E$9*H8+H5) -> 0.054659537 | I13: =I10*I3*$E$9*I8*(1-EXP(-$E$9*I8-I5))/($E$9*I8+I5) -> 0.06150786 | J13: =J10*J3*$E$9*J8*(1-EXP(-$E$9*J8-J5))/($E$9*J8+J5) -> 0.055850929 | K13: =K10*K3*$E$9*K8*(1-EXP(-$E$9*K8-K5))/($E$9*K8+K5) -> 0.048005091 | L13: =L10*L3*$E$9*L8*(1-EXP(-$E$9*L8-L5))/($E$9*L8+L5) -> 0.039784853 | M13: =M10*M3*$E$9*M8*(1-EXP(-$E$9*M8-M5))/($E$9*M8+M5) -> 0.12865983 | N13: kg
C14: Yield per recruit | D14: YPR | E14: =SUM(E13:M13) -> 0.41864035 | N14: kg
D17: Step 1. Enter X in cell B19
D18: Step 2. Find approximate F when SPR = X (i.e. find F where abs(SPR-x%) is at its minimum
D19: Step 3. Repeat column F beginning in cell F30 to lookup the F corresponding to min[abs(SPR-X)]
B20: 4 | D20: Step 4. Solution is in cell B20
A21: X = | B21: 40 | C21: %
A22: F= | B22: =VLOOKUP(E30,D30:F280,3,FALSE) -> 0.37
A27: What-If Analysis Data Table to calculate SPR and YPR for various F
A28: F | B28: SPR | C28: YPR
B29: =E12 -> 0.68533629 | C29: =E14 -> 0.41864035 | D29: abs(SPR-X) | E29: min[abs(SPR-X)] | F29: F
A30: 0.0001 | B30: 0.99952159 | C30: 0.00068128969 | D30: =ABS(B30-$B$21/100) -> 0.59952159 | E30: =MIN(D29:D280) -> 0.0021962788 | F30: =A30 -> 0.0001
A31: 0.01 | B31: 0.9544842 | C31: 0.064334346 | D31: =ABS(B31-$B$21/100) -> 0.5544842 | F31: =A31 -> 0.01
A32: 0.02 | B32: 0.91323766 | C32: 0.12173193 | D32: =ABS(B32-$B$21/100) -> 0.51323766 | F32: =A32 -> 0.02
A33: 0.03 | B33: 0.87569914 | C33: 0.17314724 | D33: =ABS(B33-$B$21/100) -> 0.47569914 | F33: =A33 -> 0.03
A34: 0.04 | B34: 0.84140099 | C34: 0.21937346 | D34: =ABS(B34-$B$21/100) -> 0.44140099 | F34: =A34 -> 0.04
A35: 0.05 | B35: 0.80995045 | C35: 0.26107473 | D35: =ABS(B35-$B$21/100) -> 0.40995045 | F35: =A35 -> 0.05
A36: 0.06 | B36: 0.78101526 | C36: 0.29881111 | D36: =ABS(B36-$B$21/100) -> 0.38101526 | F36: =A36 -> 0.06
A37: 0.07 | B37: 0.75431248 | C37: 0.33305789 | D37: =ABS(B37-$B$21/100) -> 0.35431248 | F37: =A37 -> 0.07
A38: 0.08 | B38: 0.72959967 | C38: 0.36422082 | D38: =ABS(B38-$B$21/100) -> 0.32959967 | F38: =A38 -> 0.08
A39: 0.09 | B39: 0.70666793 | C39: 0.39264817 | D39: =ABS(B39-$B$21/100) -> 0.30666793 | F39: =A39 -> 0.09
A40: 0.1 | B40: 0.68533629 | C40: 0.41864035 | D40: =ABS(B40-$B$21/100) -> 0.28533629 | F40: =A40 -> 0.1
A41: 0.11 | B41: 0.66544723 | C41: 0.44245775 | D41: =ABS(B41-$B$21/100) -> 0.26544723 | F41: =A41 -> 0.11
A42: 0.12 | B42: 0.64686299 | C42: 0.46432699 | D42: =ABS(B42-$B$21/100) -> 0.24686299 | F42: =A42 -> 0.12
... A280: 2.5 | B280: 0.16905811 | C280: 0.78511485 | D280: =ABS(B280-$B$21/100) -> 0.23094189 | F280: =A280 -> 2.5

Sheet SSB at Fx%SPR
A1: 5. Calculate equilibrium SSB at FX% (i.e. F at X% SPR) and equilibrium unfished SSB
C2: Parameter | E2: 1 | F2: 2 | G2: 3 | H2: 4 | I2: 5 | J2: 6 | K2: 7 | L2: 8 | M2: 9+ | N2: units | O2: Comments
C3: Weight-at-age | D3: w_age | E3: =phi0!E3 -> 0.5286875 | F3: =phi0!F3 -> 0.9174375 | G3: =phi0!G3 -> 1.2655 | H3: =phi0!H3 -> 1.6353958 | I3: =phi0!I3 -> 1.9437292 | J3: =phi0!J3 -> 2.2155417 | K3: =phi0!K3 -> 2.5180417 | L3: =phi0!L3 -> 2.7956042 | M3: =phi0!M3 -> 3.1556875 | N3: kg | O3: User defined: estimated from biological sampling
C4: Proportion mature | D4: m_age | E4: =phi0!E4 -> 0.18988256 | F4: =phi0!F4 -> 0.51525951 | G4: =phi0!G4 -> 0.83071832 | H4: =phi0!H4 -> 0.94003788 | I4: =phi0!I4 -> 0.97565145 | J4: =phi0!J4 -> 0.98904096 | K4: =phi0!K4 -> 0.99470052 | L4: =phi0!L4 -> 0.9973005 | M4: =phi0!M4 -> 0.99856954 | N4: - | O4: User defined: estimated from biological sampling
C5: M | D5: M_age | E5: 0.2 | F5: =E5 -> 0.2 | G5: =F5 -> 0.2 | H5: =G5 -> 0.2 | I5: =H5 -> 0.2 | J5: =I5 -> 0.2 | K5: =J5 -> 0.2 | L5: =K5 -> 0.2 | M5: =L5 -> 0.2 | N5: - | O5: User defined: model assumption
A6: Start with F = | B6: 0.1 | C6: Unfished survivorship | D6: l0_age | E6: 1 | F6: =E6*EXP(-E5) -> 0.81873075 | G6: =F6*EXP(-F5) -> 0.67032005 | H6: =G6*EXP(-G5) -> 0.54881164 | I6: =H6*EXP(-H5) -> 0.44932896 | J6: =I6*EXP(-I5) -> 0.36787944 | K6: =J6*EXP(-J5) -> 0.30119421 | L6: =K6*EXP(-K5) -> 0.24659696 | M6: =L6*EXP(-L5)/(1-EXP(-M5)) -> 1.1137935 | N6: - | O6: unfished so use F=0
C7: Unfished spawning biomass (or eggs) per recruit | D7: φ0 | E7: =SUMPRODUCT(E6:M6,E3:M3,E4:M4) -> 8.6457264 | N7: kg/recruit
C8: Vulnerability (selectivity) | D8: v_age | E8: ='phiF SPR YPR'!E8 -> 0.004043636 | F8: ='phiF SPR YPR'!F8 -> 0.048546621 | G8: ='phiF SPR YPR'!G8 -> 0.35489582 | H8: ='phiF SPR YPR'!H8 -> 0.72466873 | I8: ='phiF SPR YPR'!I8 -> 0.90894167 | J8: ='phiF SPR YPR'!J8 -> 0.97144024 | K8: ='phiF SPR YPR'!K8 -> 0.98972695 | L8: ='phiF SPR YPR'!L8 -> 0.99659089 | M8: ='phiF SPR YPR'!M8 -> 0.99806452 | N8: - | O8: User defined: Model output
C9: Fishing mortality rate | D9: F | E9: =B6 -> 0.1 | N9: -
C10: Fished survivorship | D10: lF_age | E10: 1 | F10: =E10*EXP(-E5-$E$9*E8) -> 0.81839976 | G10: =F10*EXP(-F5-$E$9*F8) -> 0.66680407 | H10: =G10*EXP(-G5-$E$9*G8) -> 0.52689784 | I10: =H10*EXP(-H5-$E$9*H8) -> 0.40123199 | J10: =I10*EXP(-I5-$E$9*I8) -> 0.29995895 | K10: =J10*EXP(-J5-$E$9*J8) -> 0.2228506 | L10: =K10*EXP(-K5-$E$9*K8) -> 0.16526147 | M10: =L10*EXP(-L5-$E$9*L8)/(1-EXP(-M5-$E$9*M8)) -> 0.47278884 | N10: -
C11: Fished spawning biomass (or eggs) per recruit | D11: φF | E11: =SUMPRODUCT(E10:M10,E3:M3,E4:M4) -> 5.9252301 | N11: kg/recruit
C12: Spawning potential ratio | D12: SPR | E12: =E11/E7 -> 0.68533629 | N12: -
C13: Yield per recruit-at-age | D13: YPR_age | E13: =E10*E3*$E$9*E8*(1-EXP(-$E$9*E8-E5))/($E$9*E8+E5) -> 0.00019372263 | F13: =F10*F3*$E$9*F8*(1-EXP(-$E$9*F8-F5))/($E$9*F8+F5) -> 0.0032959187 | G13: =G10*G3*$E$9*G8*(1-EXP(-$E$9*G8-G5))/($E$9*G8+G5) -> 0.026682616 | H13: =H10*H3*$E$9*H8*(1-EXP(-$E$9*H8-H5))/($E$9*H8+H5) -> 0.054659537 | I13: =I10*I3*$E$9*I8*(1-EXP(-$E$9*I8-I5))/($E$9*I8+I5) -> 0.06150786 | J13: =J10*J3*$E$9*J8*(1-EXP(-$E$9*J8-J5))/($E$9*J8+J5) -> 0.055850929 | K13: =K10*K3*$E$9*K8*(1-EXP(-$E$9*K8-K5))/($E$9*K8+K5) -> 0.048005091 | L13: =L10*L3*$E$9*L8*(1-EXP(-$E$9*L8-L5))/($E$9*L8+L5) -> 0.039784853 | M13: =M10*M3*$E$9*M8*(1-EXP(-$E$9*M8-M5))/($E$9*M8+M5) -> 0.12865983 | N13: kg
C14: Yield per recruit | D14: YPR | E14: =SUM(E13:M13) -> 0.41864035 | N14: kg
C15: Equilibrium unfished recruitment (no stock recruitment relationship) | D15: R0 | E15: 4.275858 | N15: 10^6 recruits | O15: User defined: Model output assuming no stock recruitment relationship
C16: Equilibrium fished SSB (no stock recruitment relationship) | D16: Eq_SSBF | E16: =E11*E15 -> 25.335442 | N16: kt | O16: This is for F in cell B6
B17: 5 | C17: Equilibrium unfished SSB (no stock recruitment relationship) | D17: SSB0 | E17: =E7*E15 -> 36.967899 | N17: kt
D20: Step 1. Equilibrium fished SSB (Eq_SSBF) is the project of the fished spawning biomass per recruit and the number of recruits
A21: X = | B21: 40 | C21: % | D21: Note: In the absence of a stock recruitment relationship, recruitment is predicted to be the unfished recruitment regardless of the SSB
A22: F= | B22: =VLOOKUP(E30,D30:F280,3,FALSE) -> 0.37 | D22: Step 2: Calculate Eq_SSBF for all F in another What-If Analysis Data Table (cell G29)
A23: =CONCATENATE("Equilibrium SSB at F at ",B21,"% SPR") -> Equilibrium SSB at F at 40% SPR | B23: 5
A24: =CONCATENATE("SSB F",B21,"%SPR =") -> SSB F40%SPR = | B24: =VLOOKUP(B22,F30:G280,2,FALSE) -> 14.868351 | C24: kt
A27: What-If Analysis Data Table to calculate SPR and YPR for various F
A28: F | B28: SPR | C28: YPR | F28: F | G28: Eq_SSBF
B29: =E12 -> 0.68533629 | C29: =E14 -> 0.41864035 | D29: abs(SPR-X) | E29: min[abs(SPR-X)] | G29: =E16 -> 25.335442
A30: 0.0001 | B30: 0.99952159 | C30: 0.00068128969 | D30: =ABS(B30-$B$21/100) -> 0.59952159 | E30: =MIN(D29:D280) -> 0.0021962788 | F30: =A30 -> 0.0001 | G30: 36.950213
A31: 0.01 | B31: 0.9544842 | C31: 0.064334346 | D31: =ABS(B31-$B$21/100) -> 0.5544842 | F31: =A31 -> 0.01 | G31: 35.285275
A32: 0.02 | B32: 0.91323766 | C32: 0.12173193 | D32: =ABS(B32-$B$21/100) -> 0.51323766 | F32: =A32 -> 0.02 | G32: 33.760477
A33: 0.03 | B33: 0.87569914 | C33: 0.17314724 | D33: =ABS(B33-$B$21/100) -> 0.47569914 | F33: =A33 -> 0.03 | G33: 32.372757
A34: 0.04 | B34: 0.84140099 | C34: 0.21937346 | D34: =ABS(B34-$B$21/100) -> 0.44140099 | F34: =A34 -> 0.04 | G34: 31.104826
A35: 0.05 | B35: 0.80995045 | C35: 0.26107473 | D35: =ABS(B35-$B$21/100) -> 0.40995045 | F35: =A35 -> 0.05 | G35: 29.942166
A36: 0.06 | B36: 0.78101526 | C36: 0.29881111 | D36: =ABS(B36-$B$21/100) -> 0.38101526 | F36: =A36 -> 0.06 | G36: 28.872493
A37: 0.07 | B37: 0.75431248 | C37: 0.33305789 | D37: =ABS(B37-$B$21/100) -> 0.35431248 | F37: =A37 -> 0.07 | G37: 27.885347
A38: 0.08 | B38: 0.72959967 | C38: 0.36422082 | D38: =ABS(B38-$B$21/100) -> 0.32959967 | F38: =A38 -> 0.08 | G38: 26.971767
A39: 0.09 | B39: 0.70666793 | C39: 0.39264817 | D39: =ABS(B39-$B$21/100) -> 0.30666793 | F39: =A39 -> 0.09 | G39: 26.124028
A40: 0.1 | B40: 0.68533629 | C40: 0.41864035 | D40: =ABS(B40-$B$21/100) -> 0.28533629 | F40: =A40 -> 0.1 | G40: 25.335442
A41: 0.11 | B41: 0.66544723 | C41: 0.44245775 | D41: =ABS(B41-$B$21/100) -> 0.26544723 | F41: =A41 -> 0.11 | G41: 24.600186
A42: 0.12 | B42: 0.64686299 | C42: 0.46432699 | D42: =ABS(B42-$B$21/100) -> 0.24686299 | F42: =A42 -> 0.12 | G42: 23.913166
... A280: 2.5 | B280: 0.16905811 | C280: 0.78511485 | D280: =ABS(B280-$B$21/100) -> 0.23094189 | F280: =A280 -> 2.5 | G280: 6.249723

Sheet SRR and Yield
A1: 6. Add a B-H SRR from steepness (h) and equilibrium unfished recruitment (R0). Or ignore R0 and h and enter a and b if a and b are provided | AB1: Recruitment (10^9) | AC1: SSB (kt) | AE1: This junk is used for the figure
C2: Parameter | E2: 1 | F2: 2 | G2: 3 | H2: 4 | I2: 5 | J2: 6 | K2: 7 | L2: 8 | M2: 9+ | N2: units | O2: Comments | AB2: =$E$17*AC2/(1+$E$18*AC2) -> 0.084453279 | AC2: 0.1 | AE2: F | AF2: =B6 -> 0.1 | AH2: SSB0
C3: Weight-at-age | D3: w_age | E3: =phi0!E3 -> 0.5286875 | F3: =phi0!F3 -> 0.9174375 | G3: =phi0!G3 -> 1.2655 | H3: =phi0!H3 -> 1.6353958 | I3: =phi0!I3 -> 1.9437292 | J3: =phi0!J3 -> 2.2155417 | K3: =phi0!K3 -> 2.5180417 | L3: =phi0!L3 -> 2.7956042 | M3: =phi0!M3 -> 3.1556875 | N3: kg | O3: User defined: estimated from biological sampling | AB3: =$E$17*AC3/(1+$E$18*AC3) -> 0.39524378 | AC3: 0.5 | AE3: =D20 -> Eq_recF | AF3: =E20 -> 3.9704702 | AG3: 0 | AH3: =E15 -> 4.275858
C4: Proportion mature | D4: m_age | E4: =phi0!E4 -> 0.18988256 | F4: =phi0!F4 -> 0.51525951 | G4: =phi0!G4 -> 0.83071832 | H4: =phi0!H4 -> 0.94003788 | I4: =phi0!I4 -> 0.97565145 | J4: =phi0!J4 -> 0.98904096 | K4: =phi0!K4 -> 0.99470052 | L4: =phi0!L4 -> 0.9973005 | M4: =phi0!M4 -> 0.99856954 | N4: - | O4: User defined: estimated from biological sampling | AB4: =$E$17*AC4/(1+$E$18*AC4) -> 0.7319378 | AC4: 1 | AE4: =D21 -> Eq_SSBF | AF4: =E21 -> 23.525949 | AH4: =E19 -> 36.967899
C5: M | D5: M_age | E5: 0.2 | F5: =E5 -> 0.2 | G5: =F5 -> 0.2 | H5: =G5 -> 0.2 | I5: =H5 -> 0.2 | J5: =I5 -> 0.2 | K5: =J5 -> 0.2 | L5: =K5 -> 0.2 | M5: =L5 -> 0.2 | N5: - | O5: User defined: model assumption | AB5: =$E$17*AC5/(1+$E$18*AC5) -> 1.2750021 | AC5: 2 | AE5: =CONCATENATE("(",AE4,",",AE3,") at F=",AF2) -> (Eq_SSBF,Eq_recF) at F=0.1
A6: Start with F = | B6: 0.1 | C6: Unfished survivorship | D6: l0_age | E6: 1 | F6: =E6*EXP(-E5) -> 0.81873075 | G6: =F6*EXP(-F5) -> 0.67032005 | H6: =G6*EXP(-G5) -> 0.54881164 | I6: =H6*EXP(-H5) -> 0.44932896 | J6: =I6*EXP(-I5) -> 0.36787944 | K6: =J6*EXP(-J5) -> 0.30119421 | L6: =K6*EXP(-K5) -> 0.24659696 | M6: =L6*EXP(-L5)/(1-EXP(-M5)) -> 1.1137935 | N6: - | O6: unfished so use F=0 | AB6: =$E$17*AC6/(1+$E$18*AC6) -> 1.6939454 | AC6: 3
A7: 7. Calculate equilbrium unfished SSB0 | C7: Unfished spawning biomass (or eggs) per recruit | D7: φ0 | E7: =SUMPRODUCT(E6:M6,E3:M3,E4:M4) -> 8.6457264 | N7: kg/recruit | AB7: =$E$17*AC7/(1+$E$18*AC7) -> 2.0269566 | AC7: 4
C8: Vulnerability (selectivity) | D8: v_age | E8: ='phiF SPR YPR'!E8 -> 0.004043636 | F8: ='phiF SPR YPR'!F8 -> 0.048546621 | G8: ='phiF SPR YPR'!G8 -> 0.35489582 | H8: ='phiF SPR YPR'!H8 -> 0.72466873 | I8: ='phiF SPR YPR'!I8 -> 0.90894167 | J8: ='phiF SPR YPR'!J8 -> 0.97144024 | K8: ='phiF SPR YPR'!K8 -> 0.98972695 | L8: ='phiF SPR YPR'!L8 -> 0.99659089 | M8: ='phiF SPR YPR'!M8 -> 0.99806452 | N8: - | O8: User defined: Model output | AB8: =$E$17*AC8/(1+$E$18*AC8) -> 2.2980154 | AC8: 5
C9: Fishing mortality rate | D9: F | E9: =B6 -> 0.1 | N9: - | AB9: =$E$17*AC9/(1+$E$18*AC9) -> 2.5229388 | AC9: 6
C10: Fished survivorship | D10: lF_age | E10: 1 | F10: =E10*EXP(-E5-$E$9*E8) -> 0.81839976 | G10: =F10*EXP(-F5-$E$9*F8) -> 0.66680407 | H10: =G10*EXP(-G5-$E$9*G8) -> 0.52689784 | I10: =H10*EXP(-H5-$E$9*H8) -> 0.40123199 | J10: =I10*EXP(-I5-$E$9*I8) -> 0.29995895 | K10: =J10*EXP(-J5-$E$9*J8) -> 0.2228506 | L10: =K10*EXP(-K5-$E$9*K8) -> 0.16526147 | M10: =L10*EXP(-L5-$E$9*L8)/(1-EXP(-M5-$E$9*M8)) -> 0.47278884 | N10: - | AB10: =$E$17*AC10/(1+$E$18*AC10) -> 2.7125816 | AC10: 7
A11: 8. Calculate equilibrium fished recruitment, equilibrium fished SSB, and Yield for a specified F (e.g. F = 0.1) | C11: Fished spawning biomass (or eggs) per recruit | D11: φF | E11: =SUMPRODUCT(E10:M10,E3:M3,E4:M4) -> 5.9252301 | N11: kg/recruit | AB11: =$E$17*AC11/(1+$E$18*AC11) -> 2.8746412 | AC11: 8
C12: Spawning potential ratio | D12: SPR | E12: =E11/E7 -> 0.68533629 | N12: - | AB12: =$E$17*AC12/(1+$E$18*AC12) -> 3.0147274 | AC12: 9
C13: Yield per recruit-at-age | D13: YPR_age | E13: =E10*E3*$E$9*E8*(1-EXP(-$E$9*E8-E5))/($E$9*E8+E5) -> 0.00019372263 | F13: =F10*F3*$E$9*F8*(1-EXP(-$E$9*F8-F5))/($E$9*F8+F5) -> 0.0032959187 | G13: =G10*G3*$E$9*G8*(1-EXP(-$E$9*G8-G5))/($E$9*G8+G5) -> 0.026682616 | H13: =H10*H3*$E$9*H8*(1-EXP(-$E$9*H8-H5))/($E$9*H8+H5) -> 0.054659537 | I13: =I10*I3*$E$9*I8*(1-EXP(-$E$9*I8-I5))/($E$9*I8+I5) -> 0.06150786 | J13: =J10*J3*$E$9*J8*(1-EXP(-$E$9*J8-J5))/($E$9*J8+J5) -> 0.055850929 | K13: =K10*K3*$E$9*K8*(1-EXP(-$E$9*K8-K5))/($E$9*K8+K5) -> 0.048005091 | L13: =L10*L3*$E$9*L8*(1-EXP(-$E$9*L8-L5))/($E$9*L8+L5) -> 0.039784853 | M13: =M10*M3*$E$9*M8*(1-EXP(-$E$9*M8-M5))/($E$9*M8+M5) -> 0.12865983 | N13: kg | AB13: =$E$17*AC13/(1+$E$18*AC13) -> 3.1370255 | AC13: 10
C14: Yield per recruit | D14: YPR | E14: =SUM(E13:M13) -> 0.41864035 | N14: kg | AB14: =$E$17*AC14/(1+$E$18*AC14) -> 3.2447214 | AC14: 11
B15: 6 | C15: Equilibrium unfished recruitment | D15: R0 | E15: 4.275858 | N15: 10^6 recruits | O15: User defined: Model output | AB15: =$E$17*AC15/(1+$E$18*AC15) -> 3.3402828 | AC15: 12
A16: 9. Calculate equilibrium SSB at 50% Rmax | B16: 6 | C16: Steepness | D16: h | E16: 0.65 | N16: - | O16: User defined: model assumption | AB16: =$E$17*AC16/(1+$E$18*AC16) -> 3.4256514 | AC16: 13
B17: 6 | C17: Beverton-Holt a | D17: a | E17: =4*E16/(E7*(1-E16)) -> 0.85921889 | N17: recruit/kg | AB17: =$E$17*AC17/(1+$E$18*AC17) -> 3.5023753 | AC17: 14
B18: 6 | C18: Beverton-Holt b | D18: b | E18: =1/E15*(E17-1/E7) -> 0.17389605 | N18: /kg | AB18: =$E$17*AC18/(1+$E$18*AC18) -> 3.5717043 | AC18: 15
B19: 7 | C19: Equilibrium unfished SSB | D19: SSB0 | E19: =E15/(E17-E18*E15) -> 36.967899 | F19: 0 | N19: kt | AB19: =$E$17*AC19/(1+$E$18*AC19) -> 3.6346584 | AC19: 16
B20: 8 | C20: Equilibrium fished recruitment | D20: Eq_recF | E20: =1/E18*(E17-1/E11) -> 3.9704702 | N20: 10^6 recruits | AB20: =$E$17*AC20/(1+$E$18*AC20) -> 3.6920782 | AC20: 17
B21: 8 | C21: Equilibrium fished SSB | D21: Eq_SSBF | E21: =E20/(E17-E20*E18) -> 23.525949 | N21: kt | AB21: =$E$17*AC21/(1+$E$18*AC21) -> 3.7446628 | AC21: 18
B22: 8 | C22: Yield | D22: Yield | E22: =MAX(E14*E20,0) -> 1.662199 | N22: kt | AB22: =$E$17*AC22/(1+$E$18*AC22) -> 3.7929982 | AC22: 19
B23: 9 | C23: Maximum recruitment from SRR | D23: Rmax | E23: =E17/E18 -> 4.9409915 | N23: 10^6 recruits | O23: Asymptotic recruitment from B-H SRR (a/b) | AB23: =$E$17*AC23/(1+$E$18*AC23) -> 3.8375795 | AC23: 20
B24: 9 | C24: Equilibrium SSB at 50%Rmax | D24: SSB50%Rmax | E24: =0.5*E23/(E17-E18*0.5*E23) -> 5.750562 | N24: kt | AB24: =$E$17*AC24/(1+$E$18*AC24) -> 3.8788277 | AC24: 21
AB25: =$E$17*AC25/(1+$E$18*AC25) -> 3.9171031 | AC25: 22
C26: Note: Stock recruitment relationship (SRR) plotted in cell T1 | AB26: =$E$17*AC26/(1+$E$18*AC26) -> 3.9527159 | AC26: 23
C27: Note: Change F in cell B6 to see how the equilibrium fished recruiment and equilibrium fished SSB shift on the SRR | AB27: =$E$17*AC27/(1+$E$18*AC27) -> 3.9859346 | AC27: 24
AB28: =$E$17*AC28/(1+$E$18*AC28) -> 4.0169928 | AC28: 25
C29: Equations | AB29: =$E$17*AC29/(1+$E$18*AC29) -> 4.0460946 | AC29: 26
C30: Beverton-Holt SRR (parameterized in terms of a and b): | F30: Note: Rmax is the asymptotic recruitment (limit as B approcahses infinte = a/b) | AB30: =$E$17*AC30/(1+$E$18*AC30) -> 4.0734192 | AC30: 27
AB31: =$E$17*AC31/(1+$E$18*AC31) -> 4.0991247 | AC31: 28
AB32: =$E$17*AC32/(1+$E$18*AC32) -> 4.1233507 | AC32: 29
C33: Beverton-Holt SRR (parameterized in terms of h and R0): | AB33: =$E$17*AC33/(1+$E$18*AC33) -> 4.1462214 | AC33: 30
AB34: =$E$17*AC34/(1+$E$18*AC34) -> 4.1678474 | AC34: 31
AB35: =$E$17*AC35/(1+$E$18*AC35) -> 4.1883278 | AC35: 32
AB36: =$E$17*AC36/(1+$E$18*AC36) -> 4.2077511 | AC36: 33
F37: Note: h depends on φ0 (the equilibrium unfished spawning biomass per recruit). The term "equilibrium" is key because φ0 depends on weight-at-age, maturity-at-age, and M | AB37: =$E$17*AC37/(1+$E$18*AC37) -> 4.2261971 | AC37: 34
F38: A B-H SRR parameterized using h and R0 and be reparmeterized in terms of a and b assuming an equilibrium unfished spawning biomass per recruit (φ0) | AB38: =$E$17*AC38/(1+$E$18*AC38) -> 4.2437378 | AC38: 35
F39: See Miller and Brooks (2021) for more details | AB39: =$E$17*AC39/(1+$E$18*AC39) -> 4.2604383 | AC39: 36
F40: https://onlinelibrary.wiley.com/doi/full/10.1111/faf.12534 | AB40: =$E$17*AC40/(1+$E$18*AC40) -> 4.2763575 | AC40: 37
...

Sheet MSY
A1: 10. Add What-If Analysis Data Table to calculate Yield for various F and estimate equilibrium MSY reference points | AB1: Recruitment (10^9) | AC1: SSB (kt)
C2: Parameter | E2: 1 | F2: 2 | G2: 3 | H2: 4 | I2: 5 | J2: 6 | K2: 7 | L2: 8 | M2: 9+ | N2: units | O2: Comments | AB2: =$E$17*AC2/(1+$E$18*AC2) -> 0.084453279 | AC2: 0.1
C3: Weight-at-age | D3: w_age | E3: =phi0!E3 -> 0.5286875 | F3: =phi0!F3 -> 0.9174375 | G3: =phi0!G3 -> 1.2655 | H3: =phi0!H3 -> 1.6353958 | I3: =phi0!I3 -> 1.9437292 | J3: =phi0!J3 -> 2.2155417 | K3: =phi0!K3 -> 2.5180417 | L3: =phi0!L3 -> 2.7956042 | M3: =phi0!M3 -> 3.1556875 | N3: kg | O3: User defined: estimated from biological sampling | AB3: =$E$17*AC3/(1+$E$18*AC3) -> 0.39524378 | AC3: 0.5
C4: Proportion mature | D4: m_age | E4: =phi0!E4 -> 0.18988256 | F4: =phi0!F4 -> 0.51525951 | G4: =phi0!G4 -> 0.83071832 | H4: =phi0!H4 -> 0.94003788 | I4: =phi0!I4 -> 0.97565145 | J4: =phi0!J4 -> 0.98904096 | K4: =phi0!K4 -> 0.99470052 | L4: =phi0!L4 -> 0.9973005 | M4: =phi0!M4 -> 0.99856954 | N4: - | O4: User defined: estimated from biological sampling | AB4: =$E$17*AC4/(1+$E$18*AC4) -> 0.7319378 | AC4: 1
C5: M | D5: M_age | E5: 0.2 | F5: =E5 -> 0.2 | G5: =F5 -> 0.2 | H5: =G5 -> 0.2 | I5: =H5 -> 0.2 | J5: =I5 -> 0.2 | K5: =J5 -> 0.2 | L5: =K5 -> 0.2 | M5: =L5 -> 0.2 | N5: - | O5: User defined: model assumption | AB5: =$E$17*AC5/(1+$E$18*AC5) -> 1.2750021 | AC5: 2
A6: Start with F = | B6: 0.1 | C6: Unfished survivorship | D6: l0_age | E6: 1 | F6: =E6*EXP(-E5) -> 0.81873075 | G6: =F6*EXP(-F5) -> 0.67032005 | H6: =G6*EXP(-G5) -> 0.54881164 | I6: =H6*EXP(-H5) -> 0.44932896 | J6: =I6*EXP(-I5) -> 0.36787944 | K6: =J6*EXP(-J5) -> 0.30119421 | L6: =K6*EXP(-K5) -> 0.24659696 | M6: =L6*EXP(-L5)/(1-EXP(-M5)) -> 1.1137935 | N6: - | O6: unfished so use F=0 | AB6: =$E$17*AC6/(1+$E$18*AC6) -> 1.6939454 | AC6: 3
C7: Unfished spawning biomass (or eggs) per recruit | D7: φ0 | E7: =SUMPRODUCT(E6:M6,E3:M3,E4:M4) -> 8.6457264 | N7: kg/recruit | AB7: =$E$17*AC7/(1+$E$18*AC7) -> 2.0269566 | AC7: 4
C8: Vulnerability (selectivity) | D8: v_age | E8: ='phiF SPR YPR'!E8 -> 0.004043636 | F8: ='phiF SPR YPR'!F8 -> 0.048546621 | G8: ='phiF SPR YPR'!G8 -> 0.35489582 | H8: ='phiF SPR YPR'!H8 -> 0.72466873 | I8: ='phiF SPR YPR'!I8 -> 0.90894167 | J8: ='phiF SPR YPR'!J8 -> 0.97144024 | K8: ='phiF SPR YPR'!K8 -> 0.98972695 | L8: ='phiF SPR YPR'!L8 -> 0.99659089 | M8: ='phiF SPR YPR'!M8 -> 0.99806452 | N8: - | O8: User defined: Model output | AB8: =$E$17*AC8/(1+$E$18*AC8) -> 2.2980154 | AC8: 5
C9: Fishing mortality rate | D9: F | E9: =B6 -> 0.1 | N9: - | AB9: =$E$17*AC9/(1+$E$18*AC9) -> 2.5229388 | AC9: 6
C10: Fished survivorship | D10: lF_age | E10: 1 | F10: =E10*EXP(-E5-$E$9*E8) -> 0.81839976 | G10: =F10*EXP(-F5-$E$9*F8) -> 0.66680407 | H10: =G10*EXP(-G5-$E$9*G8) -> 0.52689784 | I10: =H10*EXP(-H5-$E$9*H8) -> 0.40123199 | J10: =I10*EXP(-I5-$E$9*I8) -> 0.29995895 | K10: =J10*EXP(-J5-$E$9*J8) -> 0.2228506 | L10: =K10*EXP(-K5-$E$9*K8) -> 0.16526147 | M10: =L10*EXP(-L5-$E$9*L8)/(1-EXP(-M5-$E$9*M8)) -> 0.47278884 | N10: - | AB10: =$E$17*AC10/(1+$E$18*AC10) -> 2.7125816 | AC10: 7
C11: Fished spawning biomass (or eggs) per recruit | D11: φF | E11: =SUMPRODUCT(E10:M10,E3:M3,E4:M4) -> 5.9252301 | N11: kg/recruit | AB11: =$E$17*AC11/(1+$E$18*AC11) -> 2.8746412 | AC11: 8
C12: Spawning potential ratio | D12: SPR | E12: =E11/E7 -> 0.68533629 | N12: - | AB12: =$E$17*AC12/(1+$E$18*AC12) -> 3.0147274 | AC12: 9
C13: Yield per recruit-at-age | D13: YPR_age | E13: =E10*E3*$E$9*E8*(1-EXP(-$E$9*E8-E5))/($E$9*E8+E5) -> 0.00019372263 | F13: =F10*F3*$E$9*F8*(1-EXP(-$E$9*F8-F5))/($E$9*F8+F5) -> 0.0032959187 | G13: =G10*G3*$E$9*G8*(1-EXP(-$E$9*G8-G5))/($E$9*G8+G5) -> 0.026682616 | H13: =H10*H3*$E$9*H8*(1-EXP(-$E$9*H8-H5))/($E$9*H8+H5) -> 0.054659537 | I13: =I10*I3*$E$9*I8*(1-EXP(-$E$9*I8-I5))/($E$9*I8+I5) -> 0.06150786 | J13: =J10*J3*$E$9*J8*(1-EXP(-$E$9*J8-J5))/($E$9*J8+J5) -> 0.055850929 | K13: =K10*K3*$E$9*K8*(1-EXP(-$E$9*K8-K5))/($E$9*K8+K5) -> 0.048005091 | L13: =L10*L3*$E$9*L8*(1-EXP(-$E$9*L8-L5))/($E$9*L8+L5) -> 0.039784853 | M13: =M10*M3*$E$9*M8*(1-EXP(-$E$9*M8-M5))/($E$9*M8+M5) -> 0.12865983 | N13: kg | AB13: =$E$17*AC13/(1+$E$18*AC13) -> 3.1370255 | AC13: 10
C14: Yield per recruit | D14: YPR | E14: =SUM(E13:M13) -> 0.41864035 | N14: kg | AB14: =$E$17*AC14/(1+$E$18*AC14) -> 3.2447214 | AC14: 11
C15: Equilibrium unfished recruitment | D15: R0 | E15: ='SRR and Yield'!E15 -> 4.275858 | N15: 10^6 recruits | O15: User defined: Model output | U15: F | V15: MSY | X15: SSB0 | AB15: =$E$17*AC15/(1+$E$18*AC15) -> 3.3402828 | AC15: 12
C16: Steepness | D16: h | E16: 0.65 | N16: - | O16: User defined: model assumption | U16: =D20 -> Eq_recF | V16: =VLOOKUP(E27,A44:E294,5,FALSE) -> 3.353464 | W16: 0 | X16: =E15 -> 4.275858 | AB16: =$E$17*AC16/(1+$E$18*AC16) -> 3.4256514 | AC16: 13
C17: Beverton-Holt a | D17: a | E17: =4*E16/(E7*(1-E16)) -> 0.85921889 | N17: recruit/kg | U17: =D21 -> Eq_SSBF | V17: =E28 -> 12.147382 | W17: 0 | X17: =E19 -> 36.967899 | AB17: =$E$17*AC17/(1+$E$18*AC17) -> 3.5023753 | AC17: 14
C18: Beverton-Holt b | D18: b | E18: =1/E15*(E17-1/E7) -> 0.17389605 | N18: /kg | U18: =CONCATENATE("(",U17,",",U16,") at F",V15) -> (Eq_SSBF,Eq_recF) at FMSY | AB18: =$E$17*AC18/(1+$E$18*AC18) -> 3.5717043 | AC18: 15
C19: Equilibrium unfished SSB | D19: SSB0 | E19: =E15/(E17-E18*E15) -> 36.967899 | F19: 0 | N19: kt | AB19: =$E$17*AC19/(1+$E$18*AC19) -> 3.6346584 | AC19: 16
C20: Equilibrium fished recruitment | D20: Eq_recF | E20: =1/E18*(E17-1/E11) -> 3.9704702 | N20: 10^6 recruits | AB20: =$E$17*AC20/(1+$E$18*AC20) -> 3.6920782 | AC20: 17
C21: Equilibrium fished SSB | D21: Eq_SSBF | E21: =E20/(E17-E20*E18) -> 23.525949 | N21: kt | AB21: =$E$17*AC21/(1+$E$18*AC21) -> 3.7446628 | AC21: 18
C22: Yield | D22: Yield | E22: =MAX(E14*E20,0) -> 1.662199 | N22: kt | AB22: =$E$17*AC22/(1+$E$18*AC22) -> 3.7929982 | AC22: 19
C23: Maximum recruitment from SRR | D23: Rmax | E23: =E17/E18 -> 4.9409915 | N23: 10^6 recruits | O23: Asymptotic recruitment from B-H SRR | AB23: =$E$17*AC23/(1+$E$18*AC23) -> 3.8375795 | AC23: 20
C24: Equilibrium SSB at 50%Rmax | D24: SSBRmax | E24: =0.5*E23/(E17-E18*0.5*E23) -> 5.750562 | N24: kt | AB24: =$E$17*AC24/(1+$E$18*AC24) -> 3.8788277 | AC24: 21
AB25: =$E$17*AC25/(1+$E$18*AC25) -> 3.9171031 | AC25: 22
B26: 10 | C26: MSY | D26: MSY | E26: =MAX(G43:G294) -> 2.3203288 | N26: - | O26: F corresponding to max yield | AB26: =$E$17*AC26/(1+$E$18*AC26) -> 3.9527159 | AC26: 23
B27: 10 | C27: Fishing mortality at MSY | D27: FMSY | E27: =VLOOKUP(E26,G43:K544,5,FALSE) -> 0.34 | N27: kt | O27: Max yield from what-if analysis table | AB27: =$E$17*AC27/(1+$E$18*AC27) -> 3.9859346 | AC27: 24
B28: 10 | C28: Equilibrium SSBMSY | D28: SSBMSY | E28: =VLOOKUP(E27,A43:F544,6,FALSE) -> 12.147382 | N28: kt | O28: Equilibrium SSB from fishing at Fmsy | AB28: =$E$17*AC28/(1+$E$18*AC28) -> 4.0169928 | AC28: 25
AB29: =$E$17*AC29/(1+$E$18*AC29) -> 4.0460946 | AC29: 26
C30: Ratio SSBMSY/SSB0 | D30: SSBMSY/SSB0 | E30: =E28/E19 -> 0.32859272 | AB30: =$E$17*AC30/(1+$E$18*AC30) -> 4.0734192 | AC30: 27
AB31: =$E$17*AC31/(1+$E$18*AC31) -> 4.0991247 | AC31: 28
AB32: =$E$17*AC32/(1+$E$18*AC32) -> 4.1233507 | AC32: 29
C33: What-If Analysis Data Table below | AB33: =$E$17*AC33/(1+$E$18*AC33) -> 4.1462214 | AC33: 30
C34: Step 1: Find max Yield in Data Table (this is MSY) | AB34: =$E$17*AC34/(1+$E$18*AC34) -> 4.1678474 | AC34: 31
C35: Step 2: F that corresponds to MSY (vlookup) | AB35: =$E$17*AC35/(1+$E$18*AC35) -> 4.1883278 | AC35: 32
C36: Step 3: Eq_SSBF that corresponds to MSY (vlookup) | AB36: =$E$17*AC36/(1+$E$18*AC36) -> 4.2077511 | AC36: 33
AB37: =$E$17*AC37/(1+$E$18*AC37) -> 4.2261971 | AC37: 34
AB38: =$E$17*AC38/(1+$E$18*AC38) -> 4.2437378 | AC38: 35
AB39: =$E$17*AC39/(1+$E$18*AC39) -> 4.2604383 | AC39: 36
AB40: =$E$17*AC40/(1+$E$18*AC40) -> 4.2763575 | AC40: 37
...

Sheet Plots
H1: 0 | Q1: Some F options | R1: F | S1: Eq_SSB | U1: =MSY!A42 -> F | V1: =MSY!B42 -> SPR | W1: =MSY!C42 -> YPR | X1: =MSY!D42 -> φF | Y1: =MSY!E42 -> Eq_recF | Z1: =MSY!F42 -> Eq_SSBF | AA1: =MSY!G42 -> Yield | AB1: approx slope | AC1: 0.1 slope | AF1: =U1 -> F
H2: 40 | Q2: Fmax | R2: =VLOOKUP(MAX(W2:W506),W2:AF506,10,FALSE) -> 1.59 | S2: =VLOOKUP(R2,$U$2:$Z$506,6,FALSE) -> 2.918112 | V2: =MSY!B43 -> 0.68533629 | W2: =MSY!C43 -> 0.41864035 | X2: =MSY!D43 -> 5.9252301 | Y2: =MSY!E43 -> 3.9704702 | Z2: =MSY!F43 -> 23.525949 | AA2: =MSY!G43 -> 1.662199 | AF2: =U2 -> 0
Q3: F0.1 | R3: =VLOOKUP(MIN(AC5:AC506),AC5:AF506,4,FALSE) -> 0.28 | S3: =VLOOKUP(R3,$U$2:$Z$506,6,FALSE) -> 13.868509 | U3: =MSY!A44 -> 1e-06 | V3: =MSY!B44 -> 0.99999521 | W3: =MSY!C44 -> 6.8168913e-06 | X3: =MSY!D44 -> 8.645685 | Y3: =MSY!E44 -> 4.2758548 | Z3: =MSY!F44 -> 36.967694 | AA3: =MSY!G44 -> 2.9148037e-05 | AB3: =(W3)/(U3) -> 6.8168913 | AC3: =AB3*0.1 -> 0.68168913 | AF3: =U3 -> 1e-06
Q4: FMSY | R4: =MSY!E27 -> 0.34 | S4: =VLOOKUP(R4,$U$2:$Z$506,6,FALSE) -> 12.147382 | U4: =MSY!A45 -> 0.01 | V4: =MSY!B45 -> 0.9544842 | W4: =MSY!C45 -> 0.064334346 | X4: =MSY!D45 -> 8.2522092 | Y4: =MSY!E45 -> 4.2441403 | Z4: =MSY!F45 -> 35.023533 | AA4: =MSY!G45 -> 0.27304399 | AF4: =U4 -> 0.01
Q5: F0 | R5: 0 | S5: =MSY!E19 -> 36.967899 | U5: =MSY!A46 -> 0.02 | V5: =MSY!B46 -> 0.91323766 | W5: =MSY!C46 -> 0.12173193 | X5: =MSY!D46 -> 7.8956029 | Y5: =MSY!E46 -> 4.2126668 | Z5: =MSY!F46 -> 33.261545 | AA5: =MSY!G46 -> 0.51281605 | AB5: =(W6-W4)/(U6-U4) -> 5.4406448 | AC5: =ABS(AB5-$AC$3) -> 4.7589557 | AF5: =U5 -> 0.02
U6: =MSY!A47 -> 0.03 | V6: =MSY!B47 -> 0.87569914 | W6: =MSY!C47 -> 0.17314724 | X6: =MSY!D47 -> 7.5710552 | Y6: =MSY!E47 -> 4.1814458 | Z6: =MSY!F47 -> 31.657957 | AA6: =MSY!G47 -> 0.72400581 | AB6: =(W7-W5)/(U7-U5) -> 4.8820764 | AC6: =ABS(AB6-$AC$3) -> 4.2003873 | AF6: =U6 -> 0.03
U7: =MSY!A48 -> 0.04 | V7: =MSY!B48 -> 0.84140099 | W7: =MSY!C48 -> 0.21937346 | X7: =MSY!D48 -> 7.2745228 | Y7: =MSY!E48 -> 4.1504844 | Z7: =MSY!F48 -> 30.192793 | AA7: =MSY!G48 -> 0.91050609 | AB7: =(W8-W6)/(U8-U6) -> 4.3963742 | AC7: =ABS(AB7-$AC$3) -> 3.7146851 | AF7: =U7 -> 0.04
U8: =MSY!A49 -> 0.05 | V8: =MSY!B49 -> 0.80995045 | W8: =MSY!C49 -> 0.26107473 | X8: =MSY!D49 -> 7.00261 | Y8: =MSY!E49 -> 4.1197888 | Z8: =MSY!F49 -> 28.849274 | AA8: =MSY!G49 -> 1.0755727 | AB8: =(W9-W7)/(U9-U7) -> 3.9718826 | AC8: =ABS(AB8-$AC$3) -> 3.2901935 | AF8: =U8 -> 0.05
U9: =MSY!A50 -> 0.06 | V9: =MSY!B50 -> 0.78101526 | W9: =MSY!C50 -> 0.29881111 | X9: =MSY!D50 -> 6.7524443 | Y9: =MSY!E50 -> 4.0893647 | Z9: =MSY!F50 -> 27.613208 | AA9: =MSY!G50 -> 1.2219476 | AB9: =(W10-W8)/(U10-U8) -> 3.5991582 | AC9: =ABS(AB9-$AC$3) -> 2.9174691 | AF9: =U9 -> 0.06
U10: =MSY!A51 -> 0.07 | V10: =MSY!B51 -> 0.75431248 | W10: =MSY!C51 -> 0.33305789 | X10: =MSY!D51 -> 6.5215793 | Y10: =MSY!E51 -> 4.059217 | Z10: =MSY!F51 -> 26.472506 | AA10: =MSY!G51 -> 1.3519543 | AB10: =(W11-W9)/(U11-U9) -> 3.2704858 | AC10: =ABS(AB10-$AC$3) -> 2.5887967 | AF10: =U10 -> 0.07
U11: =MSY!A52 -> 0.08 | V11: =MSY!B52 -> 0.72959967 | W11: =MSY!C52 -> 0.36422082 | X11: =MSY!D52 -> 6.3079192 | Y11: =MSY!E52 -> 4.0293498 | Z11: =MSY!F52 -> 25.416813 | AA11: =MSY!G52 -> 1.4675731 | AB11: =(W12-W10)/(U12-U10) -> 2.9795139 | AC11: =ABS(AB11-$AC$3) -> 2.2978248 | AF11: =U11 -> 0.08
U12: =MSY!A53 -> 0.09 | V12: =MSY!B53 -> 0.70666793 | W12: =MSY!C53 -> 0.39264817 | X12: =MSY!D53 -> 6.1096576 | Y12: =MSY!E53 -> 3.9997665 | Z12: =MSY!F53 -> 24.437204 | AA12: =MSY!G53 -> 1.570501 | AB12: =(W13-W11)/(U13-U11) -> 2.7209765 | AC12: =ABS(AB12-$AC$3) -> 2.0392874 | AF12: =U12 -> 0.09
U13: =MSY!A54 -> 0.1 | V13: =MSY!B54 -> 0.68533629 | W13: =MSY!C54 -> 0.41864035 | X13: =MSY!D54 -> 5.9252301 | Y13: =MSY!E54 -> 3.9704702 | Z13: =MSY!F54 -> 23.525949 | AA13: =MSY!G54 -> 1.662199 | AB13: =(W14-W12)/(U14-U12) -> 2.490479 | AC13: =ABS(AB13-$AC$3) -> 1.8087899 | AF13: =U13 -> 0.1
U14: =MSY!A55 -> 0.11 | V14: =MSY!B55 -> 0.66544723 | W14: =MSY!C55 -> 0.44245775 | X14: =MSY!D55 -> 5.7532747 | Y14: =MSY!E55 -> 3.941463 | Z14: =MSY!F55 -> 22.676319 | AA14: =MSY!G55 -> 1.7439308 | AB14: =(W15-W13)/(U15-U13) -> 2.2843316 | AC14: =ABS(AB14-$AC$3) -> 1.6026424 | AF14: =U14 -> 0.11
U15: =MSY!A56 -> 0.12 | V15: =MSY!B56 -> 0.64686299 | W15: =MSY!C56 -> 0.46432699 | X15: =MSY!D56 -> 5.5926005 | Y15: =MSY!E56 -> 3.9127467 | Z15: =MSY!F56 -> 21.882429 | AA15: =MSY!G56 -> 1.8167939 | AB15: =(W16-W14)/(U16-U14) -> 2.0994188 | AC15: =ABS(AB15-$AC$3) -> 1.4177297 | AF15: =U15 -> 0.12
U16: =MSY!A57 -> 0.13 | V16: =MSY!B57 -> 0.62946262 | W16: =MSY!C57 -> 0.48444612 | X16: =MSY!D57 -> 5.4421616 | Y16: =MSY!E57 -> 3.8843227 | Z16: =MSY!F57 -> 21.139112 | AA16: =MSY!G57 -> 1.8817451 | AB16: =(W17-W15)/(U17-U15) -> 1.9330963 | AC16: =ABS(AB16-$AC$3) -> 1.2514072 | AF16: =U16 -> 0.13
U17: =MSY!A58 -> 0.14 | V17: =MSY!B58 -> 0.61313943 | W17: =MSY!C58 -> 0.50298891 | X17: =MSY!D58 -> 5.3010358 | Y17: =MSY!E58 -> 3.8561918 | Z17: =MSY!F58 -> 20.441811 | AA17: =MSY!G58 -> 1.9396217 | AB17: =(W18-W16)/(U18-U16) -> 1.7831087 | AC17: =ABS(AB17-$AC$3) -> 1.1014195 | AF17: =U17 -> 0.14
... U506: =MSY!A547 -> 35 | V506: =MSY!B547 -> 0.063405413 | W506: =MSY!C547 -> 0.69190472 | X506: =MSY!D547 -> 0.54818586 | Y506: =MSY!E547 -> -5.549177 | Z506: =MSY!F547 -> -3.0419803 | AA506: =MSY!G547 -> 0 | AB506: =(W507-W505)/(U507-U505) -> 0.036092796 | AC506: =ABS(AB506-$AC$3) -> 0.64559633 | AF506: =U506 -> 35

Sheet SR Plots with Ref Pts
F1: 0 | W1: =MSY!A42 -> F | X1: =MSY!B42 -> SPR | Y1: =MSY!C42 -> YPR | Z1: =MSY!D42 -> φF | AA1: =MSY!E42 -> Eq_recF | AB1: =MSY!F42 -> Eq_SSBF | AC1: =MSY!G42 -> Yield | AD1: SPR option1 | AE1: SPR option1 | AH1: =W1 -> F | AI1: =AB1 -> Eq_SSBF
F2: 40 | X2: =MSY!B43 -> 0.68533629 | Y2: =MSY!C43 -> 0.41864035 | Z2: =MSY!D43 -> 5.9252301 | AA2: =MSY!E43 -> 3.9704702 | AB2: =MSY!F43 -> 23.525949 | AC2: =MSY!G43 -> 1.662199
W3: =MSY!A44 -> 1e-06 | X3: =MSY!B44 -> 0.99999521 | Y3: =MSY!C44 -> 6.8168913e-06 | Z3: =MSY!D44 -> 8.645685 | AA3: =MSY!E44 -> 4.2758548 | AB3: =MSY!F44 -> 36.967694 | AC3: =MSY!G44 -> 2.9148037e-05 | AH3: =W3 -> 1e-06 | AI3: =AB3 -> 36.967694
W4: =MSY!A45 -> 0.01 | X4: =MSY!B45 -> 0.9544842 | Y4: =MSY!C45 -> 0.064334346 | Z4: =MSY!D45 -> 8.2522092 | AA4: =MSY!E45 -> 4.2441403 | AB4: =MSY!F45 -> 35.023533 | AC4: =MSY!G45 -> 0.27304399 | AD4: =ABS(X4-$C$28/100) -> 0.5544842 | AE4: =ABS(X4-$C$29/100) -> 0.6044842 | AH4: =W4 -> 0.01 | AI4: =AB4 -> 35.023533
W5: =MSY!A46 -> 0.02 | X5: =MSY!B46 -> 0.91323766 | Y5: =MSY!C46 -> 0.12173193 | Z5: =MSY!D46 -> 7.8956029 | AA5: =MSY!E46 -> 4.2126668 | AB5: =MSY!F46 -> 33.261545 | AC5: =MSY!G46 -> 0.51281605 | AD5: =ABS(X5-$C$28/100) -> 0.51323766 | AE5: =ABS(X5-$C$29/100) -> 0.56323766 | AH5: =W5 -> 0.02 | AI5: =AB5 -> 33.261545
W6: =MSY!A47 -> 0.03 | X6: =MSY!B47 -> 0.87569914 | Y6: =MSY!C47 -> 0.17314724 | Z6: =MSY!D47 -> 7.5710552 | AA6: =MSY!E47 -> 4.1814458 | AB6: =MSY!F47 -> 31.657957 | AC6: =MSY!G47 -> 0.72400581 | AD6: =ABS(X6-$C$28/100) -> 0.47569914 | AE6: =ABS(X6-$C$29/100) -> 0.52569914 | AH6: =W6 -> 0.03 | AI6: =AB6 -> 31.657957
W7: =MSY!A48 -> 0.04 | X7: =MSY!B48 -> 0.84140099 | Y7: =MSY!C48 -> 0.21937346 | Z7: =MSY!D48 -> 7.2745228 | AA7: =MSY!E48 -> 4.1504844 | AB7: =MSY!F48 -> 30.192793 | AC7: =MSY!G48 -> 0.91050609 | AD7: =ABS(X7-$C$28/100) -> 0.44140099 | AE7: =ABS(X7-$C$29/100) -> 0.49140099 | AH7: =W7 -> 0.04 | AI7: =AB7 -> 30.192793
W8: =MSY!A49 -> 0.05 | X8: =MSY!B49 -> 0.80995045 | Y8: =MSY!C49 -> 0.26107473 | Z8: =MSY!D49 -> 7.00261 | AA8: =MSY!E49 -> 4.1197888 | AB8: =MSY!F49 -> 28.849274 | AC8: =MSY!G49 -> 1.0755727 | AD8: =ABS(X8-$C$28/100) -> 0.40995045 | AE8: =ABS(X8-$C$29/100) -> 0.45995045 | AH8: =W8 -> 0.05 | AI8: =AB8 -> 28.849274
W9: =MSY!A50 -> 0.06 | X9: =MSY!B50 -> 0.78101526 | Y9: =MSY!C50 -> 0.29881111 | Z9: =MSY!D50 -> 6.7524443 | AA9: =MSY!E50 -> 4.0893647 | AB9: =MSY!F50 -> 27.613208 | AC9: =MSY!G50 -> 1.2219476 | AD9: =ABS(X9-$C$28/100) -> 0.38101526 | AE9: =ABS(X9-$C$29/100) -> 0.43101526 | AH9: =W9 -> 0.06 | AI9: =AB9 -> 27.613208
W10: =MSY!A51 -> 0.07 | X10: =MSY!B51 -> 0.75431248 | Y10: =MSY!C51 -> 0.33305789 | Z10: =MSY!D51 -> 6.5215793 | AA10: =MSY!E51 -> 4.059217 | AB10: =MSY!F51 -> 26.472506 | AC10: =MSY!G51 -> 1.3519543 | AD10: =ABS(X10-$C$28/100) -> 0.35431248 | AE10: =ABS(X10-$C$29/100) -> 0.40431248 | AH10: =W10 -> 0.07 | AI10: =AB10 -> 26.472506
W11: =MSY!A52 -> 0.08 | X11: =MSY!B52 -> 0.72959967 | Y11: =MSY!C52 -> 0.36422082 | Z11: =MSY!D52 -> 6.3079192 | AA11: =MSY!E52 -> 4.0293498 | AB11: =MSY!F52 -> 25.416813 | AC11: =MSY!G52 -> 1.4675731 | AD11: =ABS(X11-$C$28/100) -> 0.32959967 | AE11: =ABS(X11-$C$29/100) -> 0.37959967 | AH11: =W11 -> 0.08 | AI11: =AB11 -> 25.416813
W12: =MSY!A53 -> 0.09 | X12: =MSY!B53 -> 0.70666793 | Y12: =MSY!C53 -> 0.39264817 | Z12: =MSY!D53 -> 6.1096576 | AA12: =MSY!E53 -> 3.9997665 | AB12: =MSY!F53 -> 24.437204 | AC12: =MSY!G53 -> 1.570501 | AD12: =ABS(X12-$C$28/100) -> 0.30666793 | AE12: =ABS(X12-$C$29/100) -> 0.35666793 | AH12: =W12 -> 0.09 | AI12: =AB12 -> 24.437204
W13: =MSY!A54 -> 0.1 | X13: =MSY!B54 -> 0.68533629 | Y13: =MSY!C54 -> 0.41864035 | Z13: =MSY!D54 -> 5.9252301 | AA13: =MSY!E54 -> 3.9704702 | AB13: =MSY!F54 -> 23.525949 | AC13: =MSY!G54 -> 1.662199 | AD13: =ABS(X13-$C$28/100) -> 0.28533629 | AE13: =ABS(X13-$C$29/100) -> 0.33533629 | AH13: =W13 -> 0.1 | AI13: =AB13 -> 23.525949
W14: =MSY!A55 -> 0.11 | X14: =MSY!B55 -> 0.66544723 | Y14: =MSY!C55 -> 0.44245775 | Z14: =MSY!D55 -> 5.7532747 | AA14: =MSY!E55 -> 3.941463 | AB14: =MSY!F55 -> 22.676319 | AC14: =MSY!G55 -> 1.7439308 | AD14: =ABS(X14-$C$28/100) -> 0.26544723 | AE14: =ABS(X14-$C$29/100) -> 0.31544723 | AH14: =W14 -> 0.11 | AI14: =AB14 -> 22.676319
W15: =MSY!A56 -> 0.12 | X15: =MSY!B56 -> 0.64686299 | Y15: =MSY!C56 -> 0.46432699 | Z15: =MSY!D56 -> 5.5926005 | AA15: =MSY!E56 -> 3.9127467 | AB15: =MSY!F56 -> 21.882429 | AC15: =MSY!G56 -> 1.8167939 | AD15: =ABS(X15-$C$28/100) -> 0.24686299 | AE15: =ABS(X15-$C$29/100) -> 0.29686299 | AH15: =W15 -> 0.12 | AI15: =AB15 -> 21.882429
... W18: =MSY!A59 -> 0.15 | X18: =MSY!B59 -> 0.59779904 | Y18: =MSY!C59 -> 0.5201083 | Z18: =MSY!D59 -> 5.1684069 | AA18: =MSY!E59 -> 3.8283542 | AB18: =MSY!F59 -> 19.786493 | AC18: =MSY!G59 -> 1.9911588 | AD18: =ABS(X18-$C$28/100) -> 0.19779904 | AE18: =ABS(X18-$C$29/100) -> 0.24779904 | AH18: =W18 -> 0.15 | AI18: =AB18 -> 19.786493
A19: Metrics | D19: Ratio SSBMSY/SSB0 | W19: =MSY!A60 -> 0.16 | X19: =MSY!B60 -> 0.5833576 | Y19: =MSY!C60 -> 0.53593937 | Z19: =MSY!D60 -> 5.0435502 | AA19: =MSY!E60 -> 3.8008101 | AB19: =MSY!F60 -> 19.169577 | AC19: =MSY!G60 -> 2.0370038 | AD19: =ABS(X19-$C$28/100) -> 0.1833576 | AE19: =ABS(X19-$C$29/100) -> 0.2333576 | AH19: =W19 -> 0.16 | AI19: =AB19 -> 19.169577
B20: SSB0 | C20: =MSY!E19 -> 36.967899 | D20: =C21/C20 -> 0.32859272 | W20: =MSY!A61 -> 0.17 | X20: =MSY!B61 -> 0.56974041 | Y20: =MSY!C61 -> 0.55060182 | Z20: =MSY!D61 -> 4.9258198 | AA20: =MSY!E61 -> 3.773559 | AB20: =MSY!F61 -> 18.587871 | AC20: =MSY!G61 -> 2.0777284 | AD20: =ABS(X20-$C$28/100) -> 0.16974041 | AE20: =ABS(X20-$C$29/100) -> 0.21974041 | AH20: =W20 -> 0.17 | AI20: =AB20 -> 18.587871
B21: SSBMSY | C21: =MSY!E28 -> 12.147382 | W21: =MSY!A62 -> 0.18 | X21: =MSY!B62 -> 0.55688069 | Y21: =MSY!C62 -> 0.56420199 | Z21: =MSY!D62 -> 4.8146381 | AA21: =MSY!E62 -> 3.7466001 | AB21: =MSY!F62 -> 18.038524 | AC21: =MSY!G62 -> 2.1138392 | AD21: =ABS(X21-$C$28/100) -> 0.15688069 | AE21: =ABS(X21-$C$29/100) -> 0.20688069 | AH21: =W21 -> 0.18 | AI21: =AB21 -> 18.038524
W22: =MSY!A63 -> 0.19 | X22: =MSY!B63 -> 0.54471856 | Y22: =MSY!C63 -> 0.57683462 | Z22: =MSY!D63 -> 4.7094877 | AA22: =MSY!E63 -> 3.7199325 | AB22: =MSY!F63 -> 17.518977 | AC22: =MSY!G63 -> 2.1457859 | AD22: =ABS(X22-$C$28/100) -> 0.14471856 | AE22: =ABS(X22-$C$29/100) -> 0.19471856 | AH22: =W22 -> 0.19 | AI22: =AB22 -> 17.518977
A23: LRP Options | E23: SSB Value | F23: Label | W23: =MSY!A64 -> 0.2 | X23: =MSY!B64 -> 0.53320021 | Y23: =MSY!C64 -> 0.58858437 | Z23: =MSY!D64 -> 4.6099031 | AA23: =MSY!E64 -> 3.6935548 | AB23: =MSY!F64 -> 17.02693 | AC23: =MSY!G64 -> 2.1739686 | AD23: =ABS(X23-$C$28/100) -> 0.13320021 | AE23: =ABS(X23-$C$29/100) -> 0.18320021 | AH23: =W23 -> 0.2 | AI23: =AB23 -> 17.02693
A24: 1 | B24: 40 | C24: %SSBMSY | E24: =B24/100*C21 -> 4.8589529 | F24: =CONCATENATE(B24,C24) -> 40%SSBMSY | W24: =MSY!A65 -> 0.21 | X24: =MSY!B65 -> 0.52227709 | Y24: =MSY!C65 -> 0.59952703 | Z24: =MSY!D65 -> 4.5154649 | AA24: =MSY!E65 -> 3.6674654 | AB24: =MSY!F65 -> 16.560311 | AC24: =MSY!G65 -> 2.1987447 | AD24: =ABS(X24-$C$28/100) -> 0.12227709 | AE24: =ABS(X24-$C$29/100) -> 0.17227709 | AH24: =W24 -> 0.21 | AI24: =AB24 -> 16.560311
A25: 2 | B25: 50 | C25: %SSBMSY | E25: =B25/100*C21 -> 6.0736911 | F25: =CONCATENATE(B25,C25) -> 50%SSBMSY | W25: =MSY!A66 -> 0.22 | X25: =MSY!B66 -> 0.51190538 | Y25: =MSY!C66 -> 0.60973063 | Z25: =MSY!D66 -> 4.4257938 | AA25: =MSY!E66 -> 3.6416625 | AB25: =MSY!F66 -> 16.117248 | AC25: =MSY!G66 -> 2.2204332 | AD25: =ABS(X25-$C$28/100) -> 0.11190538 | AE25: =ABS(X25-$C$29/100) -> 0.16190538 | AH25: =W25 -> 0.22 | AI25: =AB25 -> 16.117248
A26: 3 | B26: 20 | C26: %SSB0 | E26: =B26/100*C20 -> 7.3935797 | F26: =CONCATENATE(B26,C26) -> 20%SSB0 | W26: =MSY!A67 -> 0.23 | X26: =MSY!B67 -> 0.50204533 | Y26: =MSY!C67 -> 0.61925638 | Z26: =MSY!D67 -> 4.3405466 | AA26: =MSY!E67 -> 3.616144 | AB26: =MSY!F67 -> 15.696042 | AC26: =MSY!G67 -> 2.2393203 | AD26: =ABS(X26-$C$28/100) -> 0.10204533 | AE26: =ABS(X26-$C$29/100) -> 0.15204533 | AH26: =W26 -> 0.23 | AI26: =AB26 -> 15.696042
A27: 4 | B27: 30 | C27: %SSB0 | E27: =B27/100*C20 -> 11.09037 | F27: =CONCATENATE(B27,C27) -> 30%SSB0 | W27: =MSY!A68 -> 0.24 | X27: =MSY!B68 -> 0.4926609 | Y27: =MSY!C68 -> 0.62815943 | Z27: =MSY!D68 -> 4.2594113 | AA27: =MSY!E68 -> 3.5909077 | AB27: =MSY!F68 -> 15.295153 | AC27: =MSY!G68 -> 2.2556626 | AD27: =ABS(X27-$C$28/100) -> 0.092660895 | AE27: =ABS(X27-$C$29/100) -> 0.1426609 | AH27: =W27 -> 0.24 | AI27: =AB27 -> 15.295153
A28: 5 | B28: =CONCATENATE("Equilibrium SSB at F =") -> Equilibrium SSB at F = | C28: 40 | D28: % SPR | E28: =VLOOKUP(MIN(AD4:AD506),AD4:AI506,6,FALSE) -> 11.430644 | F28: =CONCATENATE(C28,D28) -> 40% SPR | G28: Note: Calculated based on the stock recruitment relationship (not same as tab "SSB at Fx%SPR") | W28: =MSY!A69 -> 0.25 | X28: =MSY!B69 -> 0.48371925 | Y28: =MSY!C69 -> 0.63648962 | Z28: =MSY!D69 -> 4.1821043 | AA28: =MSY!E69 -> 3.5659511 | AB28: =MSY!F69 -> 14.91318 | AC28: =MSY!G69 -> 2.2696909 | AD28: =ABS(X28-$C$28/100) -> 0.083719247 | AE28: =ABS(X28-$C$29/100) -> 0.13371925 | AH28: =W28 -> 0.25 | AI28: =AB28 -> 14.91318
A29: 6 | B29: =CONCATENATE("Equilibrium SSB at F =") -> Equilibrium SSB at F = | C29: 35 | D29: % SPR | E29: =VLOOKUP(MIN(AE4:AE506),AE4:AI506,5,FALSE) -> 9.2189825 | F29: =CONCATENATE(C29,D29) -> 35% SPR | G29: Note: Calculated based on the stock recruitment relationship (not same as tab "SSB at Fx%SPR") | W29: =MSY!A70 -> 0.26 | X29: =MSY!B70 -> 0.47519046 | Y29: =MSY!C70 -> 0.64429205 | Z29: =MSY!D70 -> 4.1083668 | AA29: =MSY!E70 -> 3.5412717 | AB29: =MSY!F70 -> 14.548843 | AC29: =MSY!G70 -> 2.2816132 | AD29: =ABS(X29-$C$28/100) -> 0.075190465 | AE29: =ABS(X29-$C$29/100) -> 0.12519046 | AH29: =W29 -> 0.26 | AI29: =AB29 -> 14.548843
A30: 7 | B30: SSB at 50% Rmax | E30: =MSY!E24 -> 5.750562 | F30: 50%Rmax | W30: =MSY!A71 -> 0.27 | X30: =MSY!B71 -> 0.46704721 | Y30: =MSY!C71 -> 0.65160758 | Z30: =MSY!D71 -> 4.0379624 | AA30: =MSY!E71 -> 3.5168668 | AB30: =MSY!F71 -> 14.200976 | AC30: =MSY!G71 -> 2.291617 | AD30: =ABS(X30-$C$28/100) -> 0.06704721 | AE30: =ABS(X30-$C$29/100) -> 0.11704721 | AH30: =W30 -> 0.27 | AI30: =AB30 -> 14.200976
W31: =MSY!A72 -> 0.28 | X31: =MSY!B72 -> 0.45926446 | Y31: =MSY!C72 -> 0.65847334 | Z31: =MSY!D72 -> 3.9706749 | AA31: =MSY!E72 -> 3.4927334 | AB31: =MSY!F72 -> 13.868509 | AC31: =MSY!G72 -> 2.2998718 | AD31: =ABS(X31-$C$28/100) -> 0.059264458 | AE31: =ABS(X31-$C$29/100) -> 0.10926446 | AH31: =W31 -> 0.28 | AI31: =AB31 -> 13.868509
W32: =MSY!A73 -> 0.29 | X32: =MSY!B73 -> 0.45181926 | Y32: =MSY!C73 -> 0.6649231 | Z32: =MSY!D73 -> 3.9063057 | AA32: =MSY!E73 -> 3.4688686 | AB32: =MSY!F73 -> 13.550461 | AC32: =MSY!G73 -> 2.3065309 | AD32: =ABS(X32-$C$28/100) -> 0.051819261 | AE32: =ABS(X32-$C$29/100) -> 0.10181926 | AH32: =W32 -> 0.29 | AI32: =AB32 -> 13.550461
W33: =MSY!A74 -> 0.3 | X33: =MSY!B74 -> 0.44469054 | Y33: =MSY!C74 -> 0.67098763 | Z33: =MSY!D74 -> 3.8446728 | AA33: =MSY!E74 -> 3.4452694 | AB33: =MSY!F74 -> 13.245933 | AC33: =MSY!G74 -> 2.3117331 | AD33: =ABS(X33-$C$28/100) -> 0.044690541 | AE33: =ABS(X33-$C$29/100) -> 0.094690541 | AH33: =W33 -> 0.3 | AI33: =AB33 -> 13.245933
W34: =MSY!A75 -> 0.31 | X34: =MSY!B75 -> 0.4378589 | Y34: =MSY!C75 -> 0.676695 | Z34: =MSY!D75 -> 3.7856083 | AA34: =MSY!E75 -> 3.4219326 | AB34: =MSY!F75 -> 12.954096 | AC34: =MSY!G75 -> 2.3156047 | AD34: =ABS(X34-$C$28/100) -> 0.037858901 | AE34: =ABS(X34-$C$29/100) -> 0.087858901 | AH34: =W34 -> 0.31 | AI34: =AB34 -> 12.954096
W35: =MSY!A76 -> 0.32 | X35: =MSY!B76 -> 0.43130647 | Y35: =MSY!C76 -> 0.68207087 | Z35: =MSY!D76 -> 3.7289577 | AA35: =MSY!E76 -> 3.3988549 | AB35: =MSY!F76 -> 12.674186 | AC35: =MSY!G76 -> 2.3182599 | AD35: =ABS(X35-$C$28/100) -> 0.031306467 | AE35: =ABS(X35-$C$29/100) -> 0.081306467 | AH35: =W35 -> 0.32 | AI35: =AB35 -> 12.674186
W36: =MSY!A77 -> 0.33 | X36: =MSY!B77 -> 0.42501674 | Y36: =MSY!C77 -> 0.68713869 | Z36: =MSY!D77 -> 3.6745785 | AA36: =MSY!E77 -> 3.3760332 | AB36: =MSY!F77 -> 12.405499 | AC36: =MSY!G77 -> 2.319803 | AD36: =ABS(X36-$C$28/100) -> 0.025016739 | AE36: =ABS(X36-$C$29/100) -> 0.075016739 | AH36: =W36 -> 0.33 | AI36: =AB36 -> 12.405499
W37: =MSY!A78 -> 0.34 | X37: =MSY!B78 -> 0.41897447 | Y37: =MSY!C78 -> 0.69191999 | Z37: =MSY!D78 -> 3.6223386 | AA37: =MSY!E78 -> 3.353464 | AB37: =MSY!F78 -> 12.147382 | AC37: =MSY!G78 -> 2.3203288 | AD37: =ABS(X37-$C$28/100) -> 0.018974468 | AE37: =ABS(X37-$C$29/100) -> 0.068974468 | AH37: =W37 -> 0.34 | AI37: =AB37 -> 12.147382
W38: =MSY!A79 -> 0.35 | X38: =MSY!B79 -> 0.41316553 | Y38: =MSY!C79 -> 0.69643449 | Z38: =MSY!D79 -> 3.5721162 | AA38: =MSY!E79 -> 3.3311441 | AB38: =MSY!F79 -> 11.899234 | AC38: =MSY!G79 -> 2.3199236 | AD38: =ABS(X38-$C$28/100) -> 0.013165535 | AE38: =ABS(X38-$C$29/100) -> 0.063165535 | AH38: =W38 -> 0.35 | AI38: =AB38 -> 11.899234
W39: =MSY!A80 -> 0.36 | X39: =MSY!B80 -> 0.40757685 | Y39: =MSY!C80 -> 0.70070033 | Z39: =MSY!D80 -> 3.523798 | AA39: =MSY!E80 -> 3.3090699 | AB39: =MSY!F80 -> 11.660494 | AC39: =MSY!G80 -> 2.3186663 | AD39: =ABS(X39-$C$28/100) -> 0.0075768537 | AE39: =ABS(X39-$C$29/100) -> 0.057576854 | AH39: =W39 -> 0.36 | AI39: =AB39 -> 11.660494
